Workbook

Sheet Holidays & Skeleton
A1: State Holiday Reference — FY2026 & FY2027 (Weekday Holidays Only)
A3: ALL AGENCIES CLOSED
A4: Holiday | B4: Date | C4: Day of Week | D4: FY
A5: Labor Day | B5: 45901 | C5: Monday | D5: FY2026
A6: Veterans Day | B6: 45972 | C6: Tuesday | D6: FY2026
A7: Thanksgiving Day | B7: 45988 | C7: Thursday | D7: FY2026
A8: Day after Thanksgiving | B8: 45989 | C8: Friday | D8: FY2026
A9: Christmas Eve Day | B9: 46015 | C9: Wednesday | D9: FY2026
A10: Christmas Day | B10: 46016 | C10: Thursday | D10: FY2026
A11: Day after Christmas | B11: 46017 | C11: Friday | D11: FY2026
A12: New Year's Day | B12: 46023 | C12: Thursday | D12: FY2026
A13: Martin Luther King, Jr. Day | B13: 46041 | C13: Monday | D13: FY2026
A14: Presidents' Day | B14: 46069 | C14: Monday | D14: FY2026
A15: Memorial Day | B15: 46167 | C15: Monday | D15: FY2026
A16: Labor Day | B16: 46272 | C16: Monday | D16: FY2027
... A25: Memorial Day | B25: 46538 | C25: Monday | D25: FY2027
A27: SKELETON CREW DAYS
A28: Holiday | B28: Date | C28: Day of Week | D28: FY
A29: Texas Independence Day | B29: 46083 | C29: Monday | D29: FY2026
A30: San Jacinto Day | B30: 46133 | C30: Tuesday | D30: FY2026
A31: Emancipation Day | B31: 46192 | C31: Friday | D31: FY2026
A32: LBJ Day | B32: 46261 | C32: Thursday | D32: FY2026
A33: Confederate Heroes Day | B33: 46406 | C33: Tuesday | D33: FY2027
A34: Texas Independence Day | B34: 46448 | C34: Tuesday | D34: FY2027
A35: San Jacinto Day | B35: 46498 | C35: Wednesday | D35: FY2027
A36: LBJ Day | B36: 46626 | C36: Friday | D36: FY2027
A38: Weekend holidays excluded from this table.

Sheet Audit Setup
A1: Audit Configuration & Milestone Calculator | v4
A3: ANCHOR DATES
A4: Field | B4: Value | C4: Day of Week / Calc | E4: Validation / Notes
A5: Kickoff / Project Launch Date | B5: 46113 | C5: =TEXT(B5,"dddd") | E5: =IF(WEEKDAY(B5,2)=5,"⚠ Kickoff is a Friday","✓ OK")
A6: Report Release Date (auto-calculated) | B6: =WORKDAY(B5-WEEKDAY(B5,2)+1+(B16*7)-3,1,'Holidays & Skeleton'!$B$5:$B$25) | C6: =TEXT(B6,"dddd") | E6: =IF(WEEKDAY(B6,2)<>1,"⚠ Release is not Monday","✓ OK")
A7: Standard Hours Lost per Holiday/Skeleton Day | B7: 8 | C7: Deducted from resource tabs per closure. Default: 8.
A8: Weeks Before End of Fieldwork for On-Target Meeting | B8: 1 | C8: ="On-Target = "&TEXT(D13-4-$B$8*7,"MM/DD/YY dddd")&" | Buffer: "&$B$8&" wk(s)"
A10: PHASE CONFIGURATION
A11: Phase | B11: Weeks Allocated | C11: Start (Mon) | D11: End (Fri) | E11: Notes / Validation
A12: PLANNING | B12: 4 | C12: =B5-WEEKDAY(B5,2)+1 | D12: =C12+(B12-1)*7+4 | E12: Start snaps to Monday of kickoff week
A13: FIELDWORK | B13: 16 | C13: =D12+3 | D13: =C13+(B13-1)*7+4 | E13: =IF(C25-C23<28,"⚠ Writing window short","✓ OK")
A14: REPORTING | B14: 4 | C14: =D13+3 | D14: =C14+(B14-1)*7+4 | E14: Begins Monday after Fieldwork ends
A16: TOTAL AUDIT WEEKS | B16: =SUM(B12:B14) | C16: ="Audit: "&TEXT(C12,"MM/DD/YY")&" - "&TEXT(D14,"MM/DD/YY")
A18: MILESTONE CALENDAR
A19: Milestone | C19: Date | D19: Day of Week | E19: Notes / Validation
A20: Kickoff / Project Launch | C20: =B5 | D20: =IF(ISNUMBER(C20),TEXT(C20,"dddd"),"") | E20: Anchor
A21: End of Planning | C21: =D12 | D21: =IF(ISNUMBER(C21),TEXT(C21,"dddd"),"") | E21: Last Friday of Planning
A22: Outline Sent to Exec | C22: =WORKDAY(C23,-2,'Holidays & Skeleton'!$B$5:$B$25) | D22: =IF(ISNUMBER(C22),TEXT(C22,"dddd"),"") | E22: 2 business days before On-Target
A23: ON-TARGET MEETING | C23: =D13-4-$B$8*7 | D23: =IF(ISNUMBER(C23),TEXT(C23,"dddd"),"") | E23: Monday of week B8 weeks before end of Fieldwork
A24: Writing Period Begins | C24: =C23+1 | D24: =IF(ISNUMBER(C24),TEXT(C24,"dddd"),"") | E24: Day after On-Target
A25: Draft Sent to Exec | C25: =WORKDAY(C26,-3,'Holidays & Skeleton'!$B$5:$B$25) | D25: =IF(ISNUMBER(C25),TEXT(C25,"dddd"),"") | E25: =IF(C25-C23<28,"⚠ Writing window short","")
A26: Exit Conference | C26: =WORKDAY(C27,-10,'Holidays & Skeleton'!$B$5:$B$25) | D26: =IF(ISNUMBER(C26),TEXT(C26,"dddd"),"") | E26: 10 business days before Mgmt Responses Due
A27: Management Responses Due | C27: =B6-7 | D27: =IF(ISNUMBER(C27),TEXT(C27,"dddd"),"") | E27: Monday of release week minus 1 week
A28: Final Draft to Exec | C28: =B6-6 | D28: =IF(ISNUMBER(C28),TEXT(C28,"dddd"),"") | E28: Tuesday of release week
A29: Exec Approves Final Draft | C29: =B6-5 | D29: =IF(ISNUMBER(C29),TEXT(C29,"dddd"),"") | E29: Wednesday of release week
A30: PM / AM Review Prototype | C30: =B6-5 | D30: =IF(ISNUMBER(C30),TEXT(C30,"dddd"),"") | E30: Wednesday-Thursday of release week
A31: Editors Set Up Release Emails | C31: =B6-3 | D31: =IF(ISNUMBER(C31),TEXT(C31,"dddd"),"") | E31: Friday of release week
A32: REPORT RELEASE | C32: =B6 | D32: =IF(ISNUMBER(C32),TEXT(C32,"dddd"),"") | E32: =IF(WEEKDAY(B6,2)<>1,"⚠ Release not Monday","✓ OK")

Sheet Resource PM
A1: Audit Resource Tracker | v4 | PM
A2: Resource Name: | C2: PM
A3: Audit / Project: | C3: Enter audit name
A4: Phase structure driven by 'Audit Setup'. Blue = manual entry.
A6: Week # | B6: Task Assignment | C6: Week Of (Mon) | D6: Hours Avail. | E6: (-) Business Holidays | F6: (-) Skeleton Days | G6: (-) Leave Planned | H6: Total Avail. | K6: Actual Hrs | L6: Milestones This Week
A7: =" PLANNING - Weeks 1-"&'Audit Setup'!$B$12
A8: =IF(1<='Audit Setup'!$B$12,"PL-"&1,"") | C8: ='Audit Setup'!$C$12 | D8: 0 | E8: =-COUNTIFS('Holidays & Skeleton'!$B$5:$B$25,">="&C8,'Holidays & Skeleton'!$B$5:$B$25,"<="&(C8+4))*'Audit Setup'!$B$7 | F8: =-COUNTIFS('Holidays & Skeleton'!$B$29:$B$36,">="&C8,'Holidays & Skeleton'!$B$29:$B$36,"<="&(C8+4))*'Audit Setup'!$B$7 | G8: 0 | H8: =CEILING(MAX(0,SUM(D8:G8)),1) | K8: 0 | L8: =IF(NOT(ISNUMBER(C8)),"",TRIM(CONCATENATE(IF(AND('Audit Setup'!$C$20>=C8,'Audit Setup'!$C$20<=C8+4),"⚑ KICKOFF ",""),IF(AND('Audit Setup'!$C$21>=C8,'Audit Setup'!$C$21<=C8+4),"⚑ END OF PLANNING ",""),IF(AND('Audit Setup'!$C$22>=C8,'Audit Setup'!$C$22<=C8+4),"⚑ OUTLINE TO EXEC ",""),IF(AND('Audit Setup'!$C$23>=C8,'Audit Setup'!$C$23<=C8+4),"⚑ ON-TARGET ",""),IF(AND('Audit Setup'!$C$25>=C8,'Audit Setup'!$C$25<=C8+4),"⚑ DRAFT TO EXEC ",""),IF(AND('Audit Setup'!$C$26>=C8,'Audit Setup'!$C$26<=C8+4),"⚑ EXIT CONFERENCE ",""),IF(AND('Audit Setup'!$C$27>=C8,'Audit Setup'!$C$27<=C8+4),"⚑ MGMT RESPONSES DUE ",""),IF(AND('Audit Setup'!$C$32>=C8,'Audit Setup'!$C$32<=C8+4),"⚑ REPORT RELEASE ",""))))
A9: =IF(2<='Audit Setup'!$B$12,"PL-"&2,"") | C9: =C8+7 | D9: 0 | E9: =-COUNTIFS('Holidays & Skeleton'!$B$5:$B$25,">="&C9,'Holidays & Skeleton'!$B$5:$B$25,"<="&(C9+4))*'Audit Setup'!$B$7 | F9: =-COUNTIFS('Holidays & Skeleton'!$B$29:$B$36,">="&C9,'Holidays & Skeleton'!$B$29:$B$36,"<="&(C9+4))*'Audit Setup'!$B$7 | G9: 0 | H9: =CEILING(MAX(0,SUM(D9:G9)),1) | K9: 0 | L9: =IF(NOT(ISNUMBER(C9)),"",TRIM(CONCATENATE(IF(AND('Audit Setup'!$C$20>=C9,'Audit Setup'!$C$20<=C9+4),"⚑ KICKOFF ",""),IF(AND('Audit Setup'!$C$21>=C9,'Audit Setup'!$C$21<=C9+4),"⚑ END OF PLANNING ",""),IF(AND('Audit Setup'!$C$22>=C9,'Audit Setup'!$C$22<=C9+4),"⚑ OUTLINE TO EXEC ",""),IF(AND('Audit Setup'!$C$23>=C9,'Audit Setup'!$C$23<=C9+4),"⚑ ON-TARGET ",""),IF(AND('Audit Setup'!$C$25>=C9,'Audit Setup'!$C$25<=C9+4),"⚑ DRAFT TO EXEC ",""),IF(AND('Audit Setup'!$C$26>=C9,'Audit Setup'!$C$26<=C9+4),"⚑ EXIT CONFERENCE ",""),IF(AND('Audit Setup'!$C$27>=C9,'Audit Setup'!$C$27<=C9+4),"⚑ MGMT RESPONSES DUE ",""),IF(AND('Audit Setup'!$C$32>=C9,'Audit Setup'!$C$32<=C9+4),"⚑ REPORT RELEASE ",""))))
A10: =IF(3<='Audit Setup'!$B$12,"PL-"&3,"") | C10: =C9+7 | D10: 0 | E10: =-COUNTIFS('Holidays & Skeleton'!$B$5:$B$25,">="&C10,'Holidays & Skeleton'!$B$5:$B$25,"<="&(C10+4))*'Audit Setup'!$B$7 | F10: =-COUNTIFS('Holidays & Skeleton'!$B$29:$B$36,">="&C10,'Holidays & Skeleton'!$B$29:$B$36,"<="&(C10+4))*'Audit Setup'!$B$7 | G10: 0 | H10: =CEILING(MAX(0,SUM(D10:G10)),1) | K10: 0 | L10: =IF(NOT(ISNUMBER(C10)),"",TRIM(CONCATENATE(IF(AND('Audit Setup'!$C$20>=C10,'Audit Setup'!$C$20<=C10+4),"⚑ KICKOFF ",""),IF(AND('Audit Setup'!$C$21>=C10,'Audit Setup'!$C$21<=C10+4),"⚑ END OF PLANNING ",""),IF(AND('Audit Setup'!$C$22>=C10,'Audit Setup'!$C$22<=C10+4),"⚑ OUTLINE TO EXEC ",""),IF(AND('Audit Setup'!$C$23>=C10,'Audit Setup'!$C$23<=C10+4),"⚑ ON-TARGET ",""),IF(AND('Audit Setup'!$C$25>=C10,'Audit Setup'!$C$25<=C10+4),"⚑ DRAFT TO EXEC ",""),IF(AND('Audit Setup'!$C$26>=C10,'Audit Setup'!$C$26<=C10+4),"⚑ EXIT CONFERENCE ",""),IF(AND('Audit Setup'!$C$27>=C10,'Audit Setup'!$C$27<=C10+4),"⚑ MGMT RESPONSES DUE ",""),IF(AND('Audit Setup'!$C$32>=C10,'Audit Setup'!$C$32<=C10+4),"⚑ REPORT RELEASE ",""))))
A11: =IF(4<='Audit Setup'!$B$12,"PL-"&4,"") | C11: =C10+7 | D11: 0 | E11: =-COUNTIFS('Holidays & Skeleton'!$B$5:$B$25,">="&C11,'Holidays & Skeleton'!$B$5:$B$25,"<="&(C11+4))*'Audit Setup'!$B$7 | F11: =-COUNTIFS('Holidays & Skeleton'!$B$29:$B$36,">="&C11,'Holidays & Skeleton'!$B$29:$B$36,"<="&(C11+4))*'Audit Setup'!$B$7 | G11: 0 | H11: =CEILING(MAX(0,SUM(D11:G11)),1) | K11: 0 | L11: =IF(NOT(ISNUMBER(C11)),"",TRIM(CONCATENATE(IF(AND('Audit Setup'!$C$20>=C11,'Audit Setup'!$C$20<=C11+4),"⚑ KICKOFF ",""),IF(AND('Audit Setup'!$C$21>=C11,'Audit Setup'!$C$21<=C11+4),"⚑ END OF PLANNING ",""),IF(AND('Audit Setup'!$C$22>=C11,'Audit Setup'!$C$22<=C11+4),"⚑ OUTLINE TO EXEC ",""),IF(AND('Audit Setup'!$C$23>=C11,'Audit Setup'!$C$23<=C11+4),"⚑ ON-TARGET ",""),IF(AND('Audit Setup'!$C$25>=C11,'Audit Setup'!$C$25<=C11+4),"⚑ DRAFT TO EXEC ",""),IF(AND('Audit Setup'!$C$26>=C11,'Audit Setup'!$C$26<=C11+4),"⚑ EXIT CONFERENCE ",""),IF(AND('Audit Setup'!$C$27>=C11,'Audit Setup'!$C$27<=C11+4),"⚑ MGMT RESPONSES DUE ",""),IF(AND('Audit Setup'!$C$32>=C11,'Audit Setup'!$C$32<=C11+4),"⚑ REPORT RELEASE ",""))))
A12: =IF(5<='Audit Setup'!$B$12,"PL-"&5,"") | C12: =C11+7 | D12: 0 | E12: =-COUNTIFS('Holidays & Skeleton'!$B$5:$B$25,">="&C12,'Holidays & Skeleton'!$B$5:$B$25,"<="&(C12+4))*'Audit Setup'!$B$7 | F12: =-COUNTIFS('Holidays & Skeleton'!$B$29:$B$36,">="&C12,'Holidays & Skeleton'!$B$29:$B$36,"<="&(C12+4))*'Audit Setup'!$B$7 | G12: 0 | H12: =CEILING(MAX(0,SUM(D12:G12)),1) | K12: 0 | L12: =IF(NOT(ISNUMBER(C12)),"",TRIM(CONCATENATE(IF(AND('Audit Setup'!$C$20>=C12,'Audit Setup'!$C$20<=C12+4),"⚑ KICKOFF ",""),IF(AND('Audit Setup'!$C$21>=C12,'Audit Setup'!$C$21<=C12+4),"⚑ END OF PLANNING ",""),IF(AND('Audit Setup'!$C$22>=C12,'Audit Setup'!$C$22<=C12+4),"⚑ OUTLINE TO EXEC ",""),IF(AND('Audit Setup'!$C$23>=C12,'Audit Setup'!$C$23<=C12+4),"⚑ ON-TARGET ",""),IF(AND('Audit Setup'!$C$25>=C12,'Audit Setup'!$C$25<=C12+4),"⚑ DRAFT TO EXEC ",""),IF(AND('Audit Setup'!$C$26>=C12,'Audit Setup'!$C$26<=C12+4),"⚑ EXIT CONFERENCE ",""),IF(AND('Audit Setup'!$C$27>=C12,'Audit Setup'!$C$27<=C12+4),"⚑ MGMT RESPONSES DUE ",""),IF(AND('Audit Setup'!$C$32>=C12,'Audit Setup'!$C$32<=C12+4),"⚑ REPORT RELEASE ",""))))
A13: =IF(6<='Audit Setup'!$B$12,"PL-"&6,"") | C13: =C12+7 | D13: 0 | E13: =-COUNTIFS('Holidays & Skeleton'!$B$5:$B$25,">="&C13,'Holidays & Skeleton'!$B$5:$B$25,"<="&(C13+4))*'Audit Setup'!$B$7 | F13: =-COUNTIFS('Holidays & Skeleton'!$B$29:$B$36,">="&C13,'Holidays & Skeleton'!$B$29:$B$36,"<="&(C13+4))*'Audit Setup'!$B$7 | G13: 0 | H13: =CEILING(MAX(0,SUM(D13:G13)),1) | K13: 0 | L13: =IF(NOT(ISNUMBER(C13)),"",TRIM(CONCATENATE(IF(AND('Audit Setup'!$C$20>=C13,'Audit Setup'!$C$20<=C13+4),"⚑ KICKOFF ",""),IF(AND('Audit Setup'!$C$21>=C13,'Audit Setup'!$C$21<=C13+4),"⚑ END OF PLANNING ",""),IF(AND('Audit Setup'!$C$22>=C13,'Audit Setup'!$C$22<=C13+4),"⚑ OUTLINE TO EXEC ",""),IF(AND('Audit Setup'!$C$23>=C13,'Audit Setup'!$C$23<=C13+4),"⚑ ON-TARGET ",""),IF(AND('Audit Setup'!$C$25>=C13,'Audit Setup'!$C$25<=C13+4),"⚑ DRAFT TO EXEC ",""),IF(AND('Audit Setup'!$C$26>=C13,'Audit Setup'!$C$26<=C13+4),"⚑ EXIT CONFERENCE ",""),IF(AND('Audit Setup'!$C$27>=C13,'Audit Setup'!$C$27<=C13+4),"⚑ MGMT RESPONSES DUE ",""),IF(AND('Audit Setup'!$C$32>=C13,'Audit Setup'!$C$32<=C13+4),"⚑ REPORT RELEASE ",""))))
A14: =IF(7<='Audit Setup'!$B$12,"PL-"&7,"") | C14: =C13+7 | D14: 0 | E14: =-COUNTIFS('Holidays & Skeleton'!$B$5:$B$25,">="&C14,'Holidays & Skeleton'!$B$5:$B$25,"<="&(C14+4))*'Audit Setup'!$B$7 | F14: =-COUNTIFS('Holidays & Skeleton'!$B$29:$B$36,">="&C14,'Holidays & Skeleton'!$B$29:$B$36,"<="&(C14+4))*'Audit Setup'!$B$7 | G14: 0 | H14: =CEILING(MAX(0,SUM(D14:G14)),1) | K14: 0 | L14: =IF(NOT(ISNUMBER(C14)),"",TRIM(CONCATENATE(IF(AND('Audit Setup'!$C$20>=C14,'Audit Setup'!$C$20<=C14+4),"⚑ KICKOFF ",""),IF(AND('Audit Setup'!$C$21>=C14,'Audit Setup'!$C$21<=C14+4),"⚑ END OF PLANNING ",""),IF(AND('Audit Setup'!$C$22>=C14,'Audit Setup'!$C$22<=C14+4),"⚑ OUTLINE TO EXEC ",""),IF(AND('Audit Setup'!$C$23>=C14,'Audit Setup'!$C$23<=C14+4),"⚑ ON-TARGET ",""),IF(AND('Audit Setup'!$C$25>=C14,'Audit Setup'!$C$25<=C14+4),"⚑ DRAFT TO EXEC ",""),IF(AND('Audit Setup'!$C$26>=C14,'Audit Setup'!$C$26<=C14+4),"⚑ EXIT CONFERENCE ",""),IF(AND('Audit Setup'!$C$27>=C14,'Audit Setup'!$C$27<=C14+4),"⚑ MGMT RESPONSES DUE ",""),IF(AND('Audit Setup'!$C$32>=C14,'Audit Setup'!$C$32<=C14+4),"⚑ REPORT RELEASE ",""))))
A15: =IF(8<='Audit Setup'!$B$12,"PL-"&8,"") | C15: =C14+7 | D15: 0 | E15: =-COUNTIFS('Holidays & Skeleton'!$B$5:$B$25,">="&C15,'Holidays & Skeleton'!$B$5:$B$25,"<="&(C15+4))*'Audit Setup'!$B$7 | F15: =-COUNTIFS('Holidays & Skeleton'!$B$29:$B$36,">="&C15,'Holidays & Skeleton'!$B$29:$B$36,"<="&(C15+4))*'Audit Setup'!$B$7 | G15: 0 | H15: =CEILING(MAX(0,SUM(D15:G15)),1) | K15: 0 | L15: =IF(NOT(ISNUMBER(C15)),"",TRIM(CONCATENATE(IF(AND('Audit Setup'!$C$20>=C15,'Audit Setup'!$C$20<=C15+4),"⚑ KICKOFF ",""),IF(AND('Audit Setup'!$C$21>=C15,'Audit Setup'!$C$21<=C15+4),"⚑ END OF PLANNING ",""),IF(AND('Audit Setup'!$C$22>=C15,'Audit Setup'!$C$22<=C15+4),"⚑ OUTLINE TO EXEC ",""),IF(AND('Audit Setup'!$C$23>=C15,'Audit Setup'!$C$23<=C15+4),"⚑ ON-TARGET ",""),IF(AND('Audit Setup'!$C$25>=C15,'Audit Setup'!$C$25<=C15+4),"⚑ DRAFT TO EXEC ",""),IF(AND('Audit Setup'!$C$26>=C15,'Audit Setup'!$C$26<=C15+4),"⚑ EXIT CONFERENCE ",""),IF(AND('Audit Setup'!$C$27>=C15,'Audit Setup'!$C$27<=C15+4),"⚑ MGMT RESPONSES DUE ",""),IF(AND('Audit Setup'!$C$32>=C15,'Audit Setup'!$C$32<=C15+4),"⚑ REPORT RELEASE ",""))))
A16: =IF(9<='Audit Setup'!$B$12,"PL-"&9,"") | C16: =C15+7 | D16: 0 | E16: =-COUNTIFS('Holidays & Skeleton'!$B$5:$B$25,">="&C16,'Holidays & Skeleton'!$B$5:$B$25,"<="&(C16+4))*'Audit Setup'!$B$7 | F16: =-COUNTIFS('Holidays & Skeleton'!$B$29:$B$36,">="&C16,'Holidays & Skeleton'!$B$29:$B$36,"<="&(C16+4))*'Audit Setup'!$B$7 | G16: 0 | H16: =CEILING(MAX(0,SUM(D16:G16)),1) | K16: 0 | L16: =IF(NOT(ISNUMBER(C16)),"",TRIM(CONCATENATE(IF(AND('Audit Setup'!$C$20>=C16,'Audit Setup'!$C$20<=C16+4),"⚑ KICKOFF ",""),IF(AND('Audit Setup'!$C$21>=C16,'Audit Setup'!$C$21<=C16+4),"⚑ END OF PLANNING ",""),IF(AND('Audit Setup'!$C$22>=C16,'Audit Setup'!$C$22<=C16+4),"⚑ OUTLINE TO EXEC ",""),IF(AND('Audit Setup'!$C$23>=C16,'Audit Setup'!$C$23<=C16+4),"⚑ ON-TARGET ",""),IF(AND('Audit Setup'!$C$25>=C16,'Audit Setup'!$C$25<=C16+4),"⚑ DRAFT TO EXEC ",""),IF(AND('Audit Setup'!$C$26>=C16,'Audit Setup'!$C$26<=C16+4),"⚑ EXIT CONFERENCE ",""),IF(AND('Audit Setup'!$C$27>=C16,'Audit Setup'!$C$27<=C16+4),"⚑ MGMT RESPONSES DUE ",""),IF(AND('Audit Setup'!$C$32>=C16,'Audit Setup'!$C$32<=C16+4),"⚑ REPORT RELEASE ",""))))
A17: =IF(10<='Audit Setup'!$B$12,"PL-"&10,"") | C17: =C16+7 | D17: 0 | E17: =-COUNTIFS('Holidays & Skeleton'!$B$5:$B$25,">="&C17,'Holidays & Skeleton'!$B$5:$B$25,"<="&(C17+4))*'Audit Setup'!$B$7 | F17: =-COUNTIFS('Holidays & Skeleton'!$B$29:$B$36,">="&C17,'Holidays & Skeleton'!$B$29:$B$36,"<="&(C17+4))*'Audit Setup'!$B$7 | G17: 0 | H17: =CEILING(MAX(0,SUM(D17:G17)),1) | K17: 0 | L17: =IF(NOT(ISNUMBER(C17)),"",TRIM(CONCATENATE(IF(AND('Audit Setup'!$C$20>=C17,'Audit Setup'!$C$20<=C17+4),"⚑ KICKOFF ",""),IF(AND('Audit Setup'!$C$21>=C17,'Audit Setup'!$C$21<=C17+4),"⚑ END OF PLANNING ",""),IF(AND('Audit Setup'!$C$22>=C17,'Audit Setup'!$C$22<=C17+4),"⚑ OUTLINE TO EXEC ",""),IF(AND('Audit Setup'!$C$23>=C17,'Audit Setup'!$C$23<=C17+4),"⚑ ON-TARGET ",""),IF(AND('Audit Setup'!$C$25>=C17,'Audit Setup'!$C$25<=C17+4),"⚑ DRAFT TO EXEC ",""),IF(AND('Audit Setup'!$C$26>=C17,'Audit Setup'!$C$26<=C17+4),"⚑ EXIT CONFERENCE ",""),IF(AND('Audit Setup'!$C$27>=C17,'Audit Setup'!$C$27<=C17+4),"⚑ MGMT RESPONSES DUE ",""),IF(AND('Audit Setup'!$C$32>=C17,'Audit Setup'!$C$32<=C17+4),"⚑ REPORT RELEASE ",""))))
A18: =IF(11<='Audit Setup'!$B$12,"PL-"&11,"") | C18: =C17+7 | D18: 0 | E18: =-COUNTIFS('Holidays & Skeleton'!$B$5:$B$25,">="&C18,'Holidays & Skeleton'!$B$5:$B$25,"<="&(C18+4))*'Audit Setup'!$B$7 | F18: =-COUNTIFS('Holidays & Skeleton'!$B$29:$B$36,">="&C18,'Holidays & Skeleton'!$B$29:$B$36,"<="&(C18+4))*'Audit Setup'!$B$7 | G18: 0 | H18: =CEILING(MAX(0,SUM(D18:G18)),1) | K18: 0 | L18: =IF(NOT(ISNUMBER(C18)),"",TRIM(CONCATENATE(IF(AND('Audit Setup'!$C$20>=C18,'Audit Setup'!$C$20<=C18+4),"⚑ KICKOFF ",""),IF(AND('Audit Setup'!$C$21>=C18,'Audit Setup'!$C$21<=C18+4),"⚑ END OF PLANNING ",""),IF(AND('Audit Setup'!$C$22>=C18,'Audit Setup'!$C$22<=C18+4),"⚑ OUTLINE TO EXEC ",""),IF(AND('Audit Setup'!$C$23>=C18,'Audit Setup'!$C$23<=C18+4),"⚑ ON-TARGET ",""),IF(AND('Audit Setup'!$C$25>=C18,'Audit Setup'!$C$25<=C18+4),"⚑ DRAFT TO EXEC ",""),IF(AND('Audit Setup'!$C$26>=C18,'Audit Setup'!$C$26<=C18+4),"⚑ EXIT CONFERENCE ",""),IF(AND('Audit Setup'!$C$27>=C18,'Audit Setup'!$C$27<=C18+4),"⚑ MGMT RESPONSES DUE ",""),IF(AND('Audit Setup'!$C$32>=C18,'Audit Setup'!$C$32<=C18+4),"⚑ REPORT RELEASE ",""))))
A19: =IF(12<='Audit Setup'!$B$12,"PL-"&12,"") | C19: =C18+7 | D19: 0 | E19: =-COUNTIFS('Holidays & Skeleton'!$B$5:$B$25,">="&C19,'Holidays & Skeleton'!$B$5:$B$25,"<="&(C19+4))*'Audit Setup'!$B$7 | F19: =-COUNTIFS('Holidays & Skeleton'!$B$29:$B$36,">="&C19,'Holidays & Skeleton'!$B$29:$B$36,"<="&(C19+4))*'Audit Setup'!$B$7 | G19: 0 | H19: =CEILING(MAX(0,SUM(D19:G19)),1) | K19: 0 | L19: =IF(NOT(ISNUMBER(C19)),"",TRIM(CONCATENATE(IF(AND('Audit Setup'!$C$20>=C19,'Audit Setup'!$C$20<=C19+4),"⚑ KICKOFF ",""),IF(AND('Audit Setup'!$C$21>=C19,'Audit Setup'!$C$21<=C19+4),"⚑ END OF PLANNING ",""),IF(AND('Audit Setup'!$C$22>=C19,'Audit Setup'!$C$22<=C19+4),"⚑ OUTLINE TO EXEC ",""),IF(AND('Audit Setup'!$C$23>=C19,'Audit Setup'!$C$23<=C19+4),"⚑ ON-TARGET ",""),IF(AND('Audit Setup'!$C$25>=C19,'Audit Setup'!$C$25<=C19+4),"⚑ DRAFT TO EXEC ",""),IF(AND('Audit Setup'!$C$26>=C19,'Audit Setup'!$C$26<=C19+4),"⚑ EXIT CONFERENCE ",""),IF(AND('Audit Setup'!$C$27>=C19,'Audit Setup'!$C$27<=C19+4),"⚑ MGMT RESPONSES DUE ",""),IF(AND('Audit Setup'!$C$32>=C19,'Audit Setup'!$C$32<=C19+4),"⚑ REPORT RELEASE ",""))))
A20: =IF(13<='Audit Setup'!$B$12,"PL-"&13,"") | C20: =C19+7 | D20: 0 | E20: =-COUNTIFS('Holidays & Skeleton'!$B$5:$B$25,">="&C20,'Holidays & Skeleton'!$B$5:$B$25,"<="&(C20+4))*'Audit Setup'!$B$7 | F20: =-COUNTIFS('Holidays & Skeleton'!$B$29:$B$36,">="&C20,'Holidays & Skeleton'!$B$29:$B$36,"<="&(C20+4))*'Audit Setup'!$B$7 | G20: 0 | H20: =CEILING(MAX(0,SUM(D20:G20)),1) | K20: 0 | L20: =IF(NOT(ISNUMBER(C20)),"",TRIM(CONCATENATE(IF(AND('Audit Setup'!$C$20>=C20,'Audit Setup'!$C$20<=C20+4),"⚑ KICKOFF ",""),IF(AND('Audit Setup'!$C$21>=C20,'Audit Setup'!$C$21<=C20+4),"⚑ END OF PLANNING ",""),IF(AND('Audit Setup'!$C$22>=C20,'Audit Setup'!$C$22<=C20+4),"⚑ OUTLINE TO EXEC ",""),IF(AND('Audit Setup'!$C$23>=C20,'Audit Setup'!$C$23<=C20+4),"⚑ ON-TARGET ",""),IF(AND('Audit Setup'!$C$25>=C20,'Audit Setup'!$C$25<=C20+4),"⚑ DRAFT TO EXEC ",""),IF(AND('Audit Setup'!$C$26>=C20,'Audit Setup'!$C$26<=C20+4),"⚑ EXIT CONFERENCE ",""),IF(AND('Audit Setup'!$C$27>=C20,'Audit Setup'!$C$27<=C20+4),"⚑ MGMT RESPONSES DUE ",""),IF(AND('Audit Setup'!$C$32>=C20,'Audit Setup'!$C$32<=C20+4),"⚑ REPORT RELEASE ",""))))
A21: =IF(14<='Audit Setup'!$B$12,"PL-"&14,"") | C21: =C20+7 | D21: 0 | E21: =-COUNTIFS('Holidays & Skeleton'!$B$5:$B$25,">="&C21,'Holidays & Skeleton'!$B$5:$B$25,"<="&(C21+4))*'Audit Setup'!$B$7 | F21: =-COUNTIFS('Holidays & Skeleton'!$B$29:$B$36,">="&C21,'Holidays & Skeleton'!$B$29:$B$36,"<="&(C21+4))*'Audit Setup'!$B$7 | G21: 0 | H21: =CEILING(MAX(0,SUM(D21:G21)),1) | K21: 0 | L21: =IF(NOT(ISNUMBER(C21)),"",TRIM(CONCATENATE(IF(AND('Audit Setup'!$C$20>=C21,'Audit Setup'!$C$20<=C21+4),"⚑ KICKOFF ",""),IF(AND('Audit Setup'!$C$21>=C21,'Audit Setup'!$C$21<=C21+4),"⚑ END OF PLANNING ",""),IF(AND('Audit Setup'!$C$22>=C21,'Audit Setup'!$C$22<=C21+4),"⚑ OUTLINE TO EXEC ",""),IF(AND('Audit Setup'!$C$23>=C21,'Audit Setup'!$C$23<=C21+4),"⚑ ON-TARGET ",""),IF(AND('Audit Setup'!$C$25>=C21,'Audit Setup'!$C$25<=C21+4),"⚑ DRAFT TO EXEC ",""),IF(AND('Audit Setup'!$C$26>=C21,'Audit Setup'!$C$26<=C21+4),"⚑ EXIT CONFERENCE ",""),IF(AND('Audit Setup'!$C$27>=C21,'Audit Setup'!$C$27<=C21+4),"⚑ MGMT RESPONSES DUE ",""),IF(AND('Audit Setup'!$C$32>=C21,'Audit Setup'!$C$32<=C21+4),"⚑ REPORT RELEASE ",""))))
A22: =IF(15<='Audit Setup'!$B$12,"PL-"&15,"") | C22: =C21+7 | D22: 0 | E22: =-COUNTIFS('Holidays & Skeleton'!$B$5:$B$25,">="&C22,'Holidays & Skeleton'!$B$5:$B$25,"<="&(C22+4))*'Audit Setup'!$B$7 | F22: =-COUNTIFS('Holidays & Skeleton'!$B$29:$B$36,">="&C22,'Holidays & Skeleton'!$B$29:$B$36,"<="&(C22+4))*'Audit Setup'!$B$7 | G22: 0 | H22: =CEILING(MAX(0,SUM(D22:G22)),1) | K22: 0 | L22: =IF(NOT(ISNUMBER(C22)),"",TRIM(CONCATENATE(IF(AND('Audit Setup'!$C$20>=C22,'Audit Setup'!$C$20<=C22+4),"⚑ KICKOFF ",""),IF(AND('Audit Setup'!$C$21>=C22,'Audit Setup'!$C$21<=C22+4),"⚑ END OF PLANNING ",""),IF(AND('Audit Setup'!$C$22>=C22,'Audit Setup'!$C$22<=C22+4),"⚑ OUTLINE TO EXEC ",""),IF(AND('Audit Setup'!$C$23>=C22,'Audit Setup'!$C$23<=C22+4),"⚑ ON-TARGET ",""),IF(AND('Audit Setup'!$C$25>=C22,'Audit Setup'!$C$25<=C22+4),"⚑ DRAFT TO EXEC ",""),IF(AND('Audit Setup'!$C$26>=C22,'Audit Setup'!$C$26<=C22+4),"⚑ EXIT CONFERENCE ",""),IF(AND('Audit Setup'!$C$27>=C22,'Audit Setup'!$C$27<=C22+4),"⚑ MGMT RESPONSES DUE ",""),IF(AND('Audit Setup'!$C$32>=C22,'Audit Setup'!$C$32<=C22+4),"⚑ REPORT RELEASE ",""))))
A23: =IF(16<='Audit Setup'!$B$12,"PL-"&16,"") | C23: =C22+7 | D23: 0 | E23: =-COUNTIFS('Holidays & Skeleton'!$B$5:$B$25,">="&C23,'Holidays & Skeleton'!$B$5:$B$25,"<="&(C23+4))*'Audit Setup'!$B$7 | F23: =-COUNTIFS('Holidays & Skeleton'!$B$29:$B$36,">="&C23,'Holidays & Skeleton'!$B$29:$B$36,"<="&(C23+4))*'Audit Setup'!$B$7 | G23: 0 | H23: =CEILING(MAX(0,SUM(D23:G23)),1) | K23: 0 | L23: =IF(NOT(ISNUMBER(C23)),"",TRIM(CONCATENATE(IF(AND('Audit Setup'!$C$20>=C23,'Audit Setup'!$C$20<=C23+4),"⚑ KICKOFF ",""),IF(AND('Audit Setup'!$C$21>=C23,'Audit Setup'!$C$21<=C23+4),"⚑ END OF PLANNING ",""),IF(AND('Audit Setup'!$C$22>=C23,'Audit Setup'!$C$22<=C23+4),"⚑ OUTLINE TO EXEC ",""),IF(AND('Audit Setup'!$C$23>=C23,'Audit Setup'!$C$23<=C23+4),"⚑ ON-TARGET ",""),IF(AND('Audit Setup'!$C$25>=C23,'Audit Setup'!$C$25<=C23+4),"⚑ DRAFT TO EXEC ",""),IF(AND('Audit Setup'!$C$26>=C23,'Audit Setup'!$C$26<=C23+4),"⚑ EXIT CONFERENCE ",""),IF(AND('Audit Setup'!$C$27>=C23,'Audit Setup'!$C$27<=C23+4),"⚑ MGMT RESPONSES DUE ",""),IF(AND('Audit Setup'!$C$32>=C23,'Audit Setup'!$C$32<=C23+4),"⚑ REPORT RELEASE ",""))))
A24: =IF(17<='Audit Setup'!$B$12,"PL-"&17,"") | C24: =C23+7 | D24: 0 | E24: =-COUNTIFS('Holidays & Skeleton'!$B$5:$B$25,">="&C24,'Holidays & Skeleton'!$B$5:$B$25,"<="&(C24+4))*'Audit Setup'!$B$7 | F24: =-COUNTIFS('Holidays & Skeleton'!$B$29:$B$36,">="&C24,'Holidays & Skeleton'!$B$29:$B$36,"<="&(C24+4))*'Audit Setup'!$B$7 | G24: 0 | H24: =CEILING(MAX(0,SUM(D24:G24)),1) | K24: 0 | L24: =IF(NOT(ISNUMBER(C24)),"",TRIM(CONCATENATE(IF(AND('Audit Setup'!$C$20>=C24,'Audit Setup'!$C$20<=C24+4),"⚑ KICKOFF ",""),IF(AND('Audit Setup'!$C$21>=C24,'Audit Setup'!$C$21<=C24+4),"⚑ END OF PLANNING ",""),IF(AND('Audit Setup'!$C$22>=C24,'Audit Setup'!$C$22<=C24+4),"⚑ OUTLINE TO EXEC ",""),IF(AND('Audit Setup'!$C$23>=C24,'Audit Setup'!$C$23<=C24+4),"⚑ ON-TARGET ",""),IF(AND('Audit Setup'!$C$25>=C24,'Audit Setup'!$C$25<=C24+4),"⚑ DRAFT TO EXEC ",""),IF(AND('Audit Setup'!$C$26>=C24,'Audit Setup'!$C$26<=C24+4),"⚑ EXIT CONFERENCE ",""),IF(AND('Audit Setup'!$C$27>=C24,'Audit Setup'!$C$27<=C24+4),"⚑ MGMT RESPONSES DUE ",""),IF(AND('Audit Setup'!$C$32>=C24,'Audit Setup'!$C$32<=C24+4),"⚑ REPORT RELEASE ",""))))
A25: =IF(18<='Audit Setup'!$B$12,"PL-"&18,"") | C25: =C24+7 | D25: 0 | E25: =-COUNTIFS('Holidays & Skeleton'!$B$5:$B$25,">="&C25,'Holidays & Skeleton'!$B$5:$B$25,"<="&(C25+4))*'Audit Setup'!$B$7 | F25: =-COUNTIFS('Holidays & Skeleton'!$B$29:$B$36,">="&C25,'Holidays & Skeleton'!$B$29:$B$36,"<="&(C25+4))*'Audit Setup'!$B$7 | G25: 0 | H25: =CEILING(MAX(0,SUM(D25:G25)),1) | K25: 0 | L25: =IF(NOT(ISNUMBER(C25)),"",TRIM(CONCATENATE(IF(AND('Audit Setup'!$C$20>=C25,'Audit Setup'!$C$20<=C25+4),"⚑ KICKOFF ",""),IF(AND('Audit Setup'!$C$21>=C25,'Audit Setup'!$C$21<=C25+4),"⚑ END OF PLANNING ",""),IF(AND('Audit Setup'!$C$22>=C25,'Audit Setup'!$C$22<=C25+4),"⚑ OUTLINE TO EXEC ",""),IF(AND('Audit Setup'!$C$23>=C25,'Audit Setup'!$C$23<=C25+4),"⚑ ON-TARGET ",""),IF(AND('Audit Setup'!$C$25>=C25,'Audit Setup'!$C$25<=C25+4),"⚑ DRAFT TO EXEC ",""),IF(AND('Audit Setup'!$C$26>=C25,'Audit Setup'!$C$26<=C25+4),"⚑ EXIT CONFERENCE ",""),IF(AND('Audit Setup'!$C$27>=C25,'Audit Setup'!$C$27<=C25+4),"⚑ MGMT RESPONSES DUE ",""),IF(AND('Audit Setup'!$C$32>=C25,'Audit Setup'!$C$32<=C25+4),"⚑ REPORT RELEASE ",""))))
A26: =IF(19<='Audit Setup'!$B$12,"PL-"&19,"") | C26: =C25+7 | D26: 0 | E26: =-COUNTIFS('Holidays & Skeleton'!$B$5:$B$25,">="&C26,'Holidays & Skeleton'!$B$5:$B$25,"<="&(C26+4))*'Audit Setup'!$B$7 | F26: =-COUNTIFS('Holidays & Skeleton'!$B$29:$B$36,">="&C26,'Holidays & Skeleton'!$B$29:$B$36,"<="&(C26+4))*'Audit Setup'!$B$7 | G26: 0 | H26: =CEILING(MAX(0,SUM(D26:G26)),1) | K26: 0 | L26: =IF(NOT(ISNUMBER(C26)),"",TRIM(CONCATENATE(IF(AND('Audit Setup'!$C$20>=C26,'Audit Setup'!$C$20<=C26+4),"⚑ KICKOFF ",""),IF(AND('Audit Setup'!$C$21>=C26,'Audit Setup'!$C$21<=C26+4),"⚑ END OF PLANNING ",""),IF(AND('Audit Setup'!$C$22>=C26,'Audit Setup'!$C$22<=C26+4),"⚑ OUTLINE TO EXEC ",""),IF(AND('Audit Setup'!$C$23>=C26,'Audit Setup'!$C$23<=C26+4),"⚑ ON-TARGET ",""),IF(AND('Audit Setup'!$C$25>=C26,'Audit Setup'!$C$25<=C26+4),"⚑ DRAFT TO EXEC ",""),IF(AND('Audit Setup'!$C$26>=C26,'Audit Setup'!$C$26<=C26+4),"⚑ EXIT CONFERENCE ",""),IF(AND('Audit Setup'!$C$27>=C26,'Audit Setup'!$C$27<=C26+4),"⚑ MGMT RESPONSES DUE ",""),IF(AND('Audit Setup'!$C$32>=C26,'Audit Setup'!$C$32<=C26+4),"⚑ REPORT RELEASE ",""))))
A27: =IF(20<='Audit Setup'!$B$12,"PL-"&20,"") | C27: =C26+7 | D27: 0 | E27: =-COUNTIFS('Holidays & Skeleton'!$B$5:$B$25,">="&C27,'Holidays & Skeleton'!$B$5:$B$25,"<="&(C27+4))*'Audit Setup'!$B$7 | F27: =-COUNTIFS('Holidays & Skeleton'!$B$29:$B$36,">="&C27,'Holidays & Skeleton'!$B$29:$B$36,"<="&(C27+4))*'Audit Setup'!$B$7 | G27: 0 | H27: =CEILING(MAX(0,SUM(D27:G27)),1) | K27: 0 | L27: =IF(NOT(ISNUMBER(C27)),"",TRIM(CONCATENATE(IF(AND('Audit Setup'!$C$20>=C27,'Audit Setup'!$C$20<=C27+4),"⚑ KICKOFF ",""),IF(AND('Audit Setup'!$C$21>=C27,'Audit Setup'!$C$21<=C27+4),"⚑ END OF PLANNING ",""),IF(AND('Audit Setup'!$C$22>=C27,'Audit Setup'!$C$22<=C27+4),"⚑ OUTLINE TO EXEC ",""),IF(AND('Audit Setup'!$C$23>=C27,'Audit Setup'!$C$23<=C27+4),"⚑ ON-TARGET ",""),IF(AND('Audit Setup'!$C$25>=C27,'Audit Setup'!$C$25<=C27+4),"⚑ DRAFT TO EXEC ",""),IF(AND('Audit Setup'!$C$26>=C27,'Audit Setup'!$C$26<=C27+4),"⚑ EXIT CONFERENCE ",""),IF(AND('Audit Setup'!$C$27>=C27,'Audit Setup'!$C$27<=C27+4),"⚑ MGMT RESPONSES DUE ",""),IF(AND('Audit Setup'!$C$32>=C27,'Audit Setup'!$C$32<=C27+4),"⚑ REPORT RELEASE ",""))))
A28: =IF(21<='Audit Setup'!$B$12,"PL-"&21,"") | C28: =C27+7 | D28: 0 | E28: =-COUNTIFS('Holidays & Skeleton'!$B$5:$B$25,">="&C28,'Holidays & Skeleton'!$B$5:$B$25,"<="&(C28+4))*'Audit Setup'!$B$7 | F28: =-COUNTIFS('Holidays & Skeleton'!$B$29:$B$36,">="&C28,'Holidays & Skeleton'!$B$29:$B$36,"<="&(C28+4))*'Audit Setup'!$B$7 | G28: 0 | H28: =CEILING(MAX(0,SUM(D28:G28)),1) | K28: 0 | L28: =IF(NOT(ISNUMBER(C28)),"",TRIM(CONCATENATE(IF(AND('Audit Setup'!$C$20>=C28,'Audit Setup'!$C$20<=C28+4),"⚑ KICKOFF ",""),IF(AND('Audit Setup'!$C$21>=C28,'Audit Setup'!$C$21<=C28+4),"⚑ END OF PLANNING ",""),IF(AND('Audit Setup'!$C$22>=C28,'Audit Setup'!$C$22<=C28+4),"⚑ OUTLINE TO EXEC ",""),IF(AND('Audit Setup'!$C$23>=C28,'Audit Setup'!$C$23<=C28+4),"⚑ ON-TARGET ",""),IF(AND('Audit Setup'!$C$25>=C28,'Audit Setup'!$C$25<=C28+4),"⚑ DRAFT TO EXEC ",""),IF(AND('Audit Setup'!$C$26>=C28,'Audit Setup'!$C$26<=C28+4),"⚑ EXIT CONFERENCE ",""),IF(AND('Audit Setup'!$C$27>=C28,'Audit Setup'!$C$27<=C28+4),"⚑ MGMT RESPONSES DUE ",""),IF(AND('Audit Setup'!$C$32>=C28,'Audit Setup'!$C$32<=C28+4),"⚑ REPORT RELEASE ",""))))
A29: =IF(22<='Audit Setup'!$B$12,"PL-"&22,"") | C29: =C28+7 | D29: 0 | E29: =-COUNTIFS('Holidays & Skeleton'!$B$5:$B$25,">="&C29,'Holidays & Skeleton'!$B$5:$B$25,"<="&(C29+4))*'Audit Setup'!$B$7 | F29: =-COUNTIFS('Holidays & Skeleton'!$B$29:$B$36,">="&C29,'Holidays & Skeleton'!$B$29:$B$36,"<="&(C29+4))*'Audit Setup'!$B$7 | G29: 0 | H29: =CEILING(MAX(0,SUM(D29:G29)),1) | K29: 0 | L29: =IF(NOT(ISNUMBER(C29)),"",TRIM(CONCATENATE(IF(AND('Audit Setup'!$C$20>=C29,'Audit Setup'!$C$20<=C29+4),"⚑ KICKOFF ",""),IF(AND('Audit Setup'!$C$21>=C29,'Audit Setup'!$C$21<=C29+4),"⚑ END OF PLANNING ",""),IF(AND('Audit Setup'!$C$22>=C29,'Audit Setup'!$C$22<=C29+4),"⚑ OUTLINE TO EXEC ",""),IF(AND('Audit Setup'!$C$23>=C29,'Audit Setup'!$C$23<=C29+4),"⚑ ON-TARGET ",""),IF(AND('Audit Setup'!$C$25>=C29,'Audit Setup'!$C$25<=C29+4),"⚑ DRAFT TO EXEC ",""),IF(AND('Audit Setup'!$C$26>=C29,'Audit Setup'!$C$26<=C29+4),"⚑ EXIT CONFERENCE ",""),IF(AND('Audit Setup'!$C$27>=C29,'Audit Setup'!$C$27<=C29+4),"⚑ MGMT RESPONSES DUE ",""),IF(AND('Audit Setup'!$C$32>=C29,'Audit Setup'!$C$32<=C29+4),"⚑ REPORT RELEASE ",""))))
A30: =IF(23<='Audit Setup'!$B$12,"PL-"&23,"") | C30: =C29+7 | D30: 0 | E30: =-COUNTIFS('Holidays & Skeleton'!$B$5:$B$25,">="&C30,'Holidays & Skeleton'!$B$5:$B$25,"<="&(C30+4))*'Audit Setup'!$B$7 | F30: =-COUNTIFS('Holidays & Skeleton'!$B$29:$B$36,">="&C30,'Holidays & Skeleton'!$B$29:$B$36,"<="&(C30+4))*'Audit Setup'!$B$7 | G30: 0 | H30: =CEILING(MAX(0,SUM(D30:G30)),1) | K30: 0 | L30: =IF(NOT(ISNUMBER(C30)),"",TRIM(CONCATENATE(IF(AND('Audit Setup'!$C$20>=C30,'Audit Setup'!$C$20<=C30+4),"⚑ KICKOFF ",""),IF(AND('Audit Setup'!$C$21>=C30,'Audit Setup'!$C$21<=C30+4),"⚑ END OF PLANNING ",""),IF(AND('Audit Setup'!$C$22>=C30,'Audit Setup'!$C$22<=C30+4),"⚑ OUTLINE TO EXEC ",""),IF(AND('Audit Setup'!$C$23>=C30,'Audit Setup'!$C$23<=C30+4),"⚑ ON-TARGET ",""),IF(AND('Audit Setup'!$C$25>=C30,'Audit Setup'!$C$25<=C30+4),"⚑ DRAFT TO EXEC ",""),IF(AND('Audit Setup'!$C$26>=C30,'Audit Setup'!$C$26<=C30+4),"⚑ EXIT CONFERENCE ",""),IF(AND('Audit Setup'!$C$27>=C30,'Audit Setup'!$C$27<=C30+4),"⚑ MGMT RESPONSES DUE ",""),IF(AND('Audit Setup'!$C$32>=C30,'Audit Setup'!$C$32<=C30+4),"⚑ REPORT RELEASE ",""))))
A31: =IF(24<='Audit Setup'!$B$12,"PL-"&24,"") | C31: =C30+7 | D31: 0 | E31: =-COUNTIFS('Holidays & Skeleton'!$B$5:$B$25,">="&C31,'Holidays & Skeleton'!$B$5:$B$25,"<="&(C31+4))*'Audit Setup'!$B$7 | F31: =-COUNTIFS('Holidays & Skeleton'!$B$29:$B$36,">="&C31,'Holidays & Skeleton'!$B$29:$B$36,"<="&(C31+4))*'Audit Setup'!$B$7 | G31: 0 | H31: =CEILING(MAX(0,SUM(D31:G31)),1) | K31: 0 | L31: =IF(NOT(ISNUMBER(C31)),"",TRIM(CONCATENATE(IF(AND('Audit Setup'!$C$20>=C31,'Audit Setup'!$C$20<=C31+4),"⚑ KICKOFF ",""),IF(AND('Audit Setup'!$C$21>=C31,'Audit Setup'!$C$21<=C31+4),"⚑ END OF PLANNING ",""),IF(AND('Audit Setup'!$C$22>=C31,'Audit Setup'!$C$22<=C31+4),"⚑ OUTLINE TO EXEC ",""),IF(AND('Audit Setup'!$C$23>=C31,'Audit Setup'!$C$23<=C31+4),"⚑ ON-TARGET ",""),IF(AND('Audit Setup'!$C$25>=C31,'Audit Setup'!$C$25<=C31+4),"⚑ DRAFT TO EXEC ",""),IF(AND('Audit Setup'!$C$26>=C31,'Audit Setup'!$C$26<=C31+4),"⚑ EXIT CONFERENCE ",""),IF(AND('Audit Setup'!$C$27>=C31,'Audit Setup'!$C$27<=C31+4),"⚑ MGMT RESPONSES DUE ",""),IF(AND('Audit Setup'!$C$32>=C31,'Audit Setup'!$C$32<=C31+4),"⚑ REPORT RELEASE ",""))))
A32: =IF(25<='Audit Setup'!$B$12,"PL-"&25,"") | C32: =C31+7 | D32: 0 | E32: =-COUNTIFS('Holidays & Skeleton'!$B$5:$B$25,">="&C32,'Holidays & Skeleton'!$B$5:$B$25,"<="&(C32+4))*'Audit Setup'!$B$7 | F32: =-COUNTIFS('Holidays & Skeleton'!$B$29:$B$36,">="&C32,'Holidays & Skeleton'!$B$29:$B$36,"<="&(C32+4))*'Audit Setup'!$B$7 | G32: 0 | H32: =CEILING(MAX(0,SUM(D32:G32)),1) | K32: 0 | L32: =IF(NOT(ISNUMBER(C32)),"",TRIM(CONCATENATE(IF(AND('Audit Setup'!$C$20>=C32,'Audit Setup'!$C$20<=C32+4),"⚑ KICKOFF ",""),IF(AND('Audit Setup'!$C$21>=C32,'Audit Setup'!$C$21<=C32+4),"⚑ END OF PLANNING ",""),IF(AND('Audit Setup'!$C$22>=C32,'Audit Setup'!$C$22<=C32+4),"⚑ OUTLINE TO EXEC ",""),IF(AND('Audit Setup'!$C$23>=C32,'Audit Setup'!$C$23<=C32+4),"⚑ ON-TARGET ",""),IF(AND('Audit Setup'!$C$25>=C32,'Audit Setup'!$C$25<=C32+4),"⚑ DRAFT TO EXEC ",""),IF(AND('Audit Setup'!$C$26>=C32,'Audit Setup'!$C$26<=C32+4),"⚑ EXIT CONFERENCE ",""),IF(AND('Audit Setup'!$C$27>=C32,'Audit Setup'!$C$27<=C32+4),"⚑ MGMT RESPONSES DUE ",""),IF(AND('Audit Setup'!$C$32>=C32,'Audit Setup'!$C$32<=C32+4),"⚑ REPORT RELEASE ",""))))
A33: =" FIELDWORK - Weeks "&('Audit Setup'!$B$12+1)&"-"&('Audit Setup'!$B$12+'Audit Setup'!$B$13)
A34: =IF(1<='Audit Setup'!$B$13,"FW-"&1,"") | C34: ='Audit Setup'!$C$13 | D34: 0 | E34: =-COUNTIFS('Holidays & Skeleton'!$B$5:$B$25,">="&C34,'Holidays & Skeleton'!$B$5:$B$25,"<="&(C34+4))*'Audit Setup'!$B$7 | F34: =-COUNTIFS('Holidays & Skeleton'!$B$29:$B$36,">="&C34,'Holidays & Skeleton'!$B$29:$B$36,"<="&(C34+4))*'Audit Setup'!$B$7 | G34: 0 | H34: =CEILING(MAX(0,SUM(D34:G34)),1) | K34: 0 | L34: =IF(NOT(ISNUMBER(C34)),"",TRIM(CONCATENATE(IF(AND('Audit Setup'!$C$20>=C34,'Audit Setup'!$C$20<=C34+4),"⚑ KICKOFF ",""),IF(AND('Audit Setup'!$C$21>=C34,'Audit Setup'!$C$21<=C34+4),"⚑ END OF PLANNING ",""),IF(AND('Audit Setup'!$C$22>=C34,'Audit Setup'!$C$22<=C34+4),"⚑ OUTLINE TO EXEC ",""),IF(AND('Audit Setup'!$C$23>=C34,'Audit Setup'!$C$23<=C34+4),"⚑ ON-TARGET ",""),IF(AND('Audit Setup'!$C$25>=C34,'Audit Setup'!$C$25<=C34+4),"⚑ DRAFT TO EXEC ",""),IF(AND('Audit Setup'!$C$26>=C34,'Audit Setup'!$C$26<=C34+4),"⚑ EXIT CONFERENCE ",""),IF(AND('Audit Setup'!$C$27>=C34,'Audit Setup'!$C$27<=C34+4),"⚑ MGMT RESPONSES DUE ",""),IF(AND('Audit Setup'!$C$32>=C34,'Audit Setup'!$C$32<=C34+4),"⚑ REPORT RELEASE ",""))))
A35: =IF(2<='Audit Setup'!$B$13,"FW-"&2,"") | C35: =C34+7 | D35: 0 | E35: =-COUNTIFS('Holidays & Skeleton'!$B$5:$B$25,">="&C35,'Holidays & Skeleton'!$B$5:$B$25,"<="&(C35+4))*'Audit Setup'!$B$7 | F35: =-COUNTIFS('Holidays & Skeleton'!$B$29:$B$36,">="&C35,'Holidays & Skeleton'!$B$29:$B$36,"<="&(C35+4))*'Audit Setup'!$B$7 | G35: 0 | H35: =CEILING(MAX(0,SUM(D35:G35)),1) | K35: 0 | L35: =IF(NOT(ISNUMBER(C35)),"",TRIM(CONCATENATE(IF(AND('Audit Setup'!$C$20>=C35,'Audit Setup'!$C$20<=C35+4),"⚑ KICKOFF ",""),IF(AND('Audit Setup'!$C$21>=C35,'Audit Setup'!$C$21<=C35+4),"⚑ END OF PLANNING ",""),IF(AND('Audit Setup'!$C$22>=C35,'Audit Setup'!$C$22<=C35+4),"⚑ OUTLINE TO EXEC ",""),IF(AND('Audit Setup'!$C$23>=C35,'Audit Setup'!$C$23<=C35+4),"⚑ ON-TARGET ",""),IF(AND('Audit Setup'!$C$25>=C35,'Audit Setup'!$C$25<=C35+4),"⚑ DRAFT TO EXEC ",""),IF(AND('Audit Setup'!$C$26>=C35,'Audit Setup'!$C$26<=C35+4),"⚑ EXIT CONFERENCE ",""),IF(AND('Audit Setup'!$C$27>=C35,'Audit Setup'!$C$27<=C35+4),"⚑ MGMT RESPONSES DUE ",""),IF(AND('Audit Setup'!$C$32>=C35,'Audit Setup'!$C$32<=C35+4),"⚑ REPORT RELEASE ",""))))
A36: =IF(3<='Audit Setup'!$B$13,"FW-"&3,"") | C36: =C35+7 | D36: 0 | E36: =-COUNTIFS('Holidays & Skeleton'!$B$5:$B$25,">="&C36,'Holidays & Skeleton'!$B$5:$B$25,"<="&(C36+4))*'Audit Setup'!$B$7 | F36: =-COUNTIFS('Holidays & Skeleton'!$B$29:$B$36,">="&C36,'Holidays & Skeleton'!$B$29:$B$36,"<="&(C36+4))*'Audit Setup'!$B$7 | G36: 0 | H36: =CEILING(MAX(0,SUM(D36:G36)),1) | K36: 0 | L36: =IF(NOT(ISNUMBER(C36)),"",TRIM(CONCATENATE(IF(AND('Audit Setup'!$C$20>=C36,'Audit Setup'!$C$20<=C36+4),"⚑ KICKOFF ",""),IF(AND('Audit Setup'!$C$21>=C36,'Audit Setup'!$C$21<=C36+4),"⚑ END OF PLANNING ",""),IF(AND('Audit Setup'!$C$22>=C36,'Audit Setup'!$C$22<=C36+4),"⚑ OUTLINE TO EXEC ",""),IF(AND('Audit Setup'!$C$23>=C36,'Audit Setup'!$C$23<=C36+4),"⚑ ON-TARGET ",""),IF(AND('Audit Setup'!$C$25>=C36,'Audit Setup'!$C$25<=C36+4),"⚑ DRAFT TO EXEC ",""),IF(AND('Audit Setup'!$C$26>=C36,'Audit Setup'!$C$26<=C36+4),"⚑ EXIT CONFERENCE ",""),IF(AND('Audit Setup'!$C$27>=C36,'Audit Setup'!$C$27<=C36+4),"⚑ MGMT RESPONSES DUE ",""),IF(AND('Audit Setup'!$C$32>=C36,'Audit Setup'!$C$32<=C36+4),"⚑ REPORT RELEASE ",""))))
A37: =IF(4<='Audit Setup'!$B$13,"FW-"&4,"") | C37: =C36+7 | D37: 0 | E37: =-COUNTIFS('Holidays & Skeleton'!$B$5:$B$25,">="&C37,'Holidays & Skeleton'!$B$5:$B$25,"<="&(C37+4))*'Audit Setup'!$B$7 | F37: =-COUNTIFS('Holidays & Skeleton'!$B$29:$B$36,">="&C37,'Holidays & Skeleton'!$B$29:$B$36,"<="&(C37+4))*'Audit Setup'!$B$7 | G37: 0 | H37: =CEILING(MAX(0,SUM(D37:G37)),1) | K37: 0 | L37: =IF(NOT(ISNUMBER(C37)),"",TRIM(CONCATENATE(IF(AND('Audit Setup'!$C$20>=C37,'Audit Setup'!$C$20<=C37+4),"⚑ KICKOFF ",""),IF(AND('Audit Setup'!$C$21>=C37,'Audit Setup'!$C$21<=C37+4),"⚑ END OF PLANNING ",""),IF(AND('Audit Setup'!$C$22>=C37,'Audit Setup'!$C$22<=C37+4),"⚑ OUTLINE TO EXEC ",""),IF(AND('Audit Setup'!$C$23>=C37,'Audit Setup'!$C$23<=C37+4),"⚑ ON-TARGET ",""),IF(AND('Audit Setup'!$C$25>=C37,'Audit Setup'!$C$25<=C37+4),"⚑ DRAFT TO EXEC ",""),IF(AND('Audit Setup'!$C$26>=C37,'Audit Setup'!$C$26<=C37+4),"⚑ EXIT CONFERENCE ",""),IF(AND('Audit Setup'!$C$27>=C37,'Audit Setup'!$C$27<=C37+4),"⚑ MGMT RESPONSES DUE ",""),IF(AND('Audit Setup'!$C$32>=C37,'Audit Setup'!$C$32<=C37+4),"⚑ REPORT RELEASE ",""))))
A38: =IF(5<='Audit Setup'!$B$13,"FW-"&5,"") | C38: =C37+7 | D38: 0 | E38: =-COUNTIFS('Holidays & Skeleton'!$B$5:$B$25,">="&C38,'Holidays & Skeleton'!$B$5:$B$25,"<="&(C38+4))*'Audit Setup'!$B$7 | F38: =-COUNTIFS('Holidays & Skeleton'!$B$29:$B$36,">="&C38,'Holidays & Skeleton'!$B$29:$B$36,"<="&(C38+4))*'Audit Setup'!$B$7 | G38: 0 | H38: =CEILING(MAX(0,SUM(D38:G38)),1) | K38: 0 | L38: =IF(NOT(ISNUMBER(C38)),"",TRIM(CONCATENATE(IF(AND('Audit Setup'!$C$20>=C38,'Audit Setup'!$C$20<=C38+4),"⚑ KICKOFF ",""),IF(AND('Audit Setup'!$C$21>=C38,'Audit Setup'!$C$21<=C38+4),"⚑ END OF PLANNING ",""),IF(AND('Audit Setup'!$C$22>=C38,'Audit Setup'!$C$22<=C38+4),"⚑ OUTLINE TO EXEC ",""),IF(AND('Audit Setup'!$C$23>=C38,'Audit Setup'!$C$23<=C38+4),"⚑ ON-TARGET ",""),IF(AND('Audit Setup'!$C$25>=C38,'Audit Setup'!$C$25<=C38+4),"⚑ DRAFT TO EXEC ",""),IF(AND('Audit Setup'!$C$26>=C38,'Audit Setup'!$C$26<=C38+4),"⚑ EXIT CONFERENCE ",""),IF(AND('Audit Setup'!$C$27>=C38,'Audit Setup'!$C$27<=C38+4),"⚑ MGMT RESPONSES DUE ",""),IF(AND('Audit Setup'!$C$32>=C38,'Audit Setup'!$C$32<=C38+4),"⚑ REPORT RELEASE ",""))))
A39: =IF(6<='Audit Setup'!$B$13,"FW-"&6,"") | C39: =C38+7 | D39: 0 | E39: =-COUNTIFS('Holidays & Skeleton'!$B$5:$B$25,">="&C39,'Holidays & Skeleton'!$B$5:$B$25,"<="&(C39+4))*'Audit Setup'!$B$7 | F39: =-COUNTIFS('Holidays & Skeleton'!$B$29:$B$36,">="&C39,'Holidays & Skeleton'!$B$29:$B$36,"<="&(C39+4))*'Audit Setup'!$B$7 | G39: 0 | H39: =CEILING(MAX(0,SUM(D39:G39)),1) | K39: 0 | L39: =IF(NOT(ISNUMBER(C39)),"",TRIM(CONCATENATE(IF(AND('Audit Setup'!$C$20>=C39,'Audit Setup'!$C$20<=C39+4),"⚑ KICKOFF ",""),IF(AND('Audit Setup'!$C$21>=C39,'Audit Setup'!$C$21<=C39+4),"⚑ END OF PLANNING ",""),IF(AND('Audit Setup'!$C$22>=C39,'Audit Setup'!$C$22<=C39+4),"⚑ OUTLINE TO EXEC ",""),IF(AND('Audit Setup'!$C$23>=C39,'Audit Setup'!$C$23<=C39+4),"⚑ ON-TARGET ",""),IF(AND('Audit Setup'!$C$25>=C39,'Audit Setup'!$C$25<=C39+4),"⚑ DRAFT TO EXEC ",""),IF(AND('Audit Setup'!$C$26>=C39,'Audit Setup'!$C$26<=C39+4),"⚑ EXIT CONFERENCE ",""),IF(AND('Audit Setup'!$C$27>=C39,'Audit Setup'!$C$27<=C39+4),"⚑ MGMT RESPONSES DUE ",""),IF(AND('Audit Setup'!$C$32>=C39,'Audit Setup'!$C$32<=C39+4),"⚑ REPORT RELEASE ",""))))
A40: =IF(7<='Audit Setup'!$B$13,"FW-"&7,"") | C40: =C39+7 | D40: 0 | E40: =-COUNTIFS('Holidays & Skeleton'!$B$5:$B$25,">="&C40,'Holidays & Skeleton'!$B$5:$B$25,"<="&(C40+4))*'Audit Setup'!$B$7 | F40: =-COUNTIFS('Holidays & Skeleton'!$B$29:$B$36,">="&C40,'Holidays & Skeleton'!$B$29:$B$36,"<="&(C40+4))*'Audit Setup'!$B$7 | G40: 0 | H40: =CEILING(MAX(0,SUM(D40:G40)),1) | K40: 0 | L40: =IF(NOT(ISNUMBER(C40)),"",TRIM(CONCATENATE(IF(AND('Audit Setup'!$C$20>=C40,'Audit Setup'!$C$20<=C40+4),"⚑ KICKOFF ",""),IF(AND('Audit Setup'!$C$21>=C40,'Audit Setup'!$C$21<=C40+4),"⚑ END OF PLANNING ",""),IF(AND('Audit Setup'!$C$22>=C40,'Audit Setup'!$C$22<=C40+4),"⚑ OUTLINE TO EXEC ",""),IF(AND('Audit Setup'!$C$23>=C40,'Audit Setup'!$C$23<=C40+4),"⚑ ON-TARGET ",""),IF(AND('Audit Setup'!$C$25>=C40,'Audit Setup'!$C$25<=C40+4),"⚑ DRAFT TO EXEC ",""),IF(AND('Audit Setup'!$C$26>=C40,'Audit Setup'!$C$26<=C40+4),"⚑ EXIT CONFERENCE ",""),IF(AND('Audit Setup'!$C$27>=C40,'Audit Setup'!$C$27<=C40+4),"⚑ MGMT RESPONSES DUE ",""),IF(AND('Audit Setup'!$C$32>=C40,'Audit Setup'!$C$32<=C40+4),"⚑ REPORT RELEASE ",""))))
A41: =IF(8<='Audit Setup'!$B$13,"FW-"&8,"") | C41: =C40+7 | D41: 0 | E41: =-COUNTIFS('Holidays & Skeleton'!$B$5:$B$25,">="&C41,'Holidays & Skeleton'!$B$5:$B$25,"<="&(C41+4))*'Audit Setup'!$B$7 | F41: =-COUNTIFS('Holidays & Skeleton'!$B$29:$B$36,">="&C41,'Holidays & Skeleton'!$B$29:$B$36,"<="&(C41+4))*'Audit Setup'!$B$7 | G41: 0 | H41: =CEILING(MAX(0,SUM(D41:G41)),1) | K41: 0 | L41: =IF(NOT(ISNUMBER(C41)),"",TRIM(CONCATENATE(IF(AND('Audit Setup'!$C$20>=C41,'Audit Setup'!$C$20<=C41+4),"⚑ KICKOFF ",""),IF(AND('Audit Setup'!$C$21>=C41,'Audit Setup'!$C$21<=C41+4),"⚑ END OF PLANNING ",""),IF(AND('Audit Setup'!$C$22>=C41,'Audit Setup'!$C$22<=C41+4),"⚑ OUTLINE TO EXEC ",""),IF(AND('Audit Setup'!$C$23>=C41,'Audit Setup'!$C$23<=C41+4),"⚑ ON-TARGET ",""),IF(AND('Audit Setup'!$C$25>=C41,'Audit Setup'!$C$25<=C41+4),"⚑ DRAFT TO EXEC ",""),IF(AND('Audit Setup'!$C$26>=C41,'Audit Setup'!$C$26<=C41+4),"⚑ EXIT CONFERENCE ",""),IF(AND('Audit Setup'!$C$27>=C41,'Audit Setup'!$C$27<=C41+4),"⚑ MGMT RESPONSES DUE ",""),IF(AND('Audit Setup'!$C$32>=C41,'Audit Setup'!$C$32<=C41+4),"⚑ REPORT RELEASE ",""))))
...

Sheet Resource Asst PM
A1: Audit Resource Tracker | v4 | Asst PM
A2: Resource Name: | C2: Asst PM
A3: Audit / Project: | C3: Enter audit name
A4: Phase structure driven by 'Audit Setup'. Blue = manual entry.
A6: Week # | B6: Task Assignment | C6: Week Of (Mon) | D6: Hours Avail. | E6: (-) Business Holidays | F6: (-) Skeleton Days | G6: (-) Leave Planned | H6: Total Avail. | K6: Actual Hrs | L6: Milestones This Week
A7: =" PLANNING - Weeks 1-"&'Audit Setup'!$B$12
A8: =IF(1<='Audit Setup'!$B$12,"PL-"&1,"") | C8: ='Audit Setup'!$C$12 | D8: 0 | E8: =-COUNTIFS('Holidays & Skeleton'!$B$5:$B$25,">="&C8,'Holidays & Skeleton'!$B$5:$B$25,"<="&(C8+4))*'Audit Setup'!$B$7 | F8: =-COUNTIFS('Holidays & Skeleton'!$B$29:$B$36,">="&C8,'Holidays & Skeleton'!$B$29:$B$36,"<="&(C8+4))*'Audit Setup'!$B$7 | G8: 0 | H8: =CEILING(MAX(0,SUM(D8:G8)),1) | K8: 0 | L8: =IF(NOT(ISNUMBER(C8)),"",TRIM(CONCATENATE(IF(AND('Audit Setup'!$C$20>=C8,'Audit Setup'!$C$20<=C8+4),"⚑ KICKOFF ",""),IF(AND('Audit Setup'!$C$21>=C8,'Audit Setup'!$C$21<=C8+4),"⚑ END OF PLANNING ",""),IF(AND('Audit Setup'!$C$22>=C8,'Audit Setup'!$C$22<=C8+4),"⚑ OUTLINE TO EXEC ",""),IF(AND('Audit Setup'!$C$23>=C8,'Audit Setup'!$C$23<=C8+4),"⚑ ON-TARGET ",""),IF(AND('Audit Setup'!$C$25>=C8,'Audit Setup'!$C$25<=C8+4),"⚑ DRAFT TO EXEC ",""),IF(AND('Audit Setup'!$C$26>=C8,'Audit Setup'!$C$26<=C8+4),"⚑ EXIT CONFERENCE ",""),IF(AND('Audit Setup'!$C$27>=C8,'Audit Setup'!$C$27<=C8+4),"⚑ MGMT RESPONSES DUE ",""),IF(AND('Audit Setup'!$C$32>=C8,'Audit Setup'!$C$32<=C8+4),"⚑ REPORT RELEASE ",""))))
A9: =IF(2<='Audit Setup'!$B$12,"PL-"&2,"") | C9: =C8+7 | D9: 0 | E9: =-COUNTIFS('Holidays & Skeleton'!$B$5:$B$25,">="&C9,'Holidays & Skeleton'!$B$5:$B$25,"<="&(C9+4))*'Audit Setup'!$B$7 | F9: =-COUNTIFS('Holidays & Skeleton'!$B$29:$B$36,">="&C9,'Holidays & Skeleton'!$B$29:$B$36,"<="&(C9+4))*'Audit Setup'!$B$7 | G9: 0 | H9: =CEILING(MAX(0,SUM(D9:G9)),1) | K9: 0 | L9: =IF(NOT(ISNUMBER(C9)),"",TRIM(CONCATENATE(IF(AND('Audit Setup'!$C$20>=C9,'Audit Setup'!$C$20<=C9+4),"⚑ KICKOFF ",""),IF(AND('Audit Setup'!$C$21>=C9,'Audit Setup'!$C$21<=C9+4),"⚑ END OF PLANNING ",""),IF(AND('Audit Setup'!$C$22>=C9,'Audit Setup'!$C$22<=C9+4),"⚑ OUTLINE TO EXEC ",""),IF(AND('Audit Setup'!$C$23>=C9,'Audit Setup'!$C$23<=C9+4),"⚑ ON-TARGET ",""),IF(AND('Audit Setup'!$C$25>=C9,'Audit Setup'!$C$25<=C9+4),"⚑ DRAFT TO EXEC ",""),IF(AND('Audit Setup'!$C$26>=C9,'Audit Setup'!$C$26<=C9+4),"⚑ EXIT CONFERENCE ",""),IF(AND('Audit Setup'!$C$27>=C9,'Audit Setup'!$C$27<=C9+4),"⚑ MGMT RESPONSES DUE ",""),IF(AND('Audit Setup'!$C$32>=C9,'Audit Setup'!$C$32<=C9+4),"⚑ REPORT RELEASE ",""))))
A10: =IF(3<='Audit Setup'!$B$12,"PL-"&3,"") | C10: =C9+7 | D10: 0 | E10: =-COUNTIFS('Holidays & Skeleton'!$B$5:$B$25,">="&C10,'Holidays & Skeleton'!$B$5:$B$25,"<="&(C10+4))*'Audit Setup'!$B$7 | F10: =-COUNTIFS('Holidays & Skeleton'!$B$29:$B$36,">="&C10,'Holidays & Skeleton'!$B$29:$B$36,"<="&(C10+4))*'Audit Setup'!$B$7 | G10: 0 | H10: =CEILING(MAX(0,SUM(D10:G10)),1) | K10: 0 | L10: =IF(NOT(ISNUMBER(C10)),"",TRIM(CONCATENATE(IF(AND('Audit Setup'!$C$20>=C10,'Audit Setup'!$C$20<=C10+4),"⚑ KICKOFF ",""),IF(AND('Audit Setup'!$C$21>=C10,'Audit Setup'!$C$21<=C10+4),"⚑ END OF PLANNING ",""),IF(AND('Audit Setup'!$C$22>=C10,'Audit Setup'!$C$22<=C10+4),"⚑ OUTLINE TO EXEC ",""),IF(AND('Audit Setup'!$C$23>=C10,'Audit Setup'!$C$23<=C10+4),"⚑ ON-TARGET ",""),IF(AND('Audit Setup'!$C$25>=C10,'Audit Setup'!$C$25<=C10+4),"⚑ DRAFT TO EXEC ",""),IF(AND('Audit Setup'!$C$26>=C10,'Audit Setup'!$C$26<=C10+4),"⚑ EXIT CONFERENCE ",""),IF(AND('Audit Setup'!$C$27>=C10,'Audit Setup'!$C$27<=C10+4),"⚑ MGMT RESPONSES DUE ",""),IF(AND('Audit Setup'!$C$32>=C10,'Audit Setup'!$C$32<=C10+4),"⚑ REPORT RELEASE ",""))))
A11: =IF(4<='Audit Setup'!$B$12,"PL-"&4,"") | C11: =C10+7 | D11: 0 | E11: =-COUNTIFS('Holidays & Skeleton'!$B$5:$B$25,">="&C11,'Holidays & Skeleton'!$B$5:$B$25,"<="&(C11+4))*'Audit Setup'!$B$7 | F11: =-COUNTIFS('Holidays & Skeleton'!$B$29:$B$36,">="&C11,'Holidays & Skeleton'!$B$29:$B$36,"<="&(C11+4))*'Audit Setup'!$B$7 | G11: 0 | H11: =CEILING(MAX(0,SUM(D11:G11)),1) | K11: 0 | L11: =IF(NOT(ISNUMBER(C11)),"",TRIM(CONCATENATE(IF(AND('Audit Setup'!$C$20>=C11,'Audit Setup'!$C$20<=C11+4),"⚑ KICKOFF ",""),IF(AND('Audit Setup'!$C$21>=C11,'Audit Setup'!$C$21<=C11+4),"⚑ END OF PLANNING ",""),IF(AND('Audit Setup'!$C$22>=C11,'Audit Setup'!$C$22<=C11+4),"⚑ OUTLINE TO EXEC ",""),IF(AND('Audit Setup'!$C$23>=C11,'Audit Setup'!$C$23<=C11+4),"⚑ ON-TARGET ",""),IF(AND('Audit Setup'!$C$25>=C11,'Audit Setup'!$C$25<=C11+4),"⚑ DRAFT TO EXEC ",""),IF(AND('Audit Setup'!$C$26>=C11,'Audit Setup'!$C$26<=C11+4),"⚑ EXIT CONFERENCE ",""),IF(AND('Audit Setup'!$C$27>=C11,'Audit Setup'!$C$27<=C11+4),"⚑ MGMT RESPONSES DUE ",""),IF(AND('Audit Setup'!$C$32>=C11,'Audit Setup'!$C$32<=C11+4),"⚑ REPORT RELEASE ",""))))
A12: =IF(5<='Audit Setup'!$B$12,"PL-"&5,"") | C12: =C11+7 | D12: 0 | E12: =-COUNTIFS('Holidays & Skeleton'!$B$5:$B$25,">="&C12,'Holidays & Skeleton'!$B$5:$B$25,"<="&(C12+4))*'Audit Setup'!$B$7 | F12: =-COUNTIFS('Holidays & Skeleton'!$B$29:$B$36,">="&C12,'Holidays & Skeleton'!$B$29:$B$36,"<="&(C12+4))*'Audit Setup'!$B$7 | G12: 0 | H12: =CEILING(MAX(0,SUM(D12:G12)),1) | K12: 0 | L12: =IF(NOT(ISNUMBER(C12)),"",TRIM(CONCATENATE(IF(AND('Audit Setup'!$C$20>=C12,'Audit Setup'!$C$20<=C12+4),"⚑ KICKOFF ",""),IF(AND('Audit Setup'!$C$21>=C12,'Audit Setup'!$C$21<=C12+4),"⚑ END OF PLANNING ",""),IF(AND('Audit Setup'!$C$22>=C12,'Audit Setup'!$C$22<=C12+4),"⚑ OUTLINE TO EXEC ",""),IF(AND('Audit Setup'!$C$23>=C12,'Audit Setup'!$C$23<=C12+4),"⚑ ON-TARGET ",""),IF(AND('Audit Setup'!$C$25>=C12,'Audit Setup'!$C$25<=C12+4),"⚑ DRAFT TO EXEC ",""),IF(AND('Audit Setup'!$C$26>=C12,'Audit Setup'!$C$26<=C12+4),"⚑ EXIT CONFERENCE ",""),IF(AND('Audit Setup'!$C$27>=C12,'Audit Setup'!$C$27<=C12+4),"⚑ MGMT RESPONSES DUE ",""),IF(AND('Audit Setup'!$C$32>=C12,'Audit Setup'!$C$32<=C12+4),"⚑ REPORT RELEASE ",""))))
A13: =IF(6<='Audit Setup'!$B$12,"PL-"&6,"") | C13: =C12+7 | D13: 0 | E13: =-COUNTIFS('Holidays & Skeleton'!$B$5:$B$25,">="&C13,'Holidays & Skeleton'!$B$5:$B$25,"<="&(C13+4))*'Audit Setup'!$B$7 | F13: =-COUNTIFS('Holidays & Skeleton'!$B$29:$B$36,">="&C13,'Holidays & Skeleton'!$B$29:$B$36,"<="&(C13+4))*'Audit Setup'!$B$7 | G13: 0 | H13: =CEILING(MAX(0,SUM(D13:G13)),1) | K13: 0 | L13: =IF(NOT(ISNUMBER(C13)),"",TRIM(CONCATENATE(IF(AND('Audit Setup'!$C$20>=C13,'Audit Setup'!$C$20<=C13+4),"⚑ KICKOFF ",""),IF(AND('Audit Setup'!$C$21>=C13,'Audit Setup'!$C$21<=C13+4),"⚑ END OF PLANNING ",""),IF(AND('Audit Setup'!$C$22>=C13,'Audit Setup'!$C$22<=C13+4),"⚑ OUTLINE TO EXEC ",""),IF(AND('Audit Setup'!$C$23>=C13,'Audit Setup'!$C$23<=C13+4),"⚑ ON-TARGET ",""),IF(AND('Audit Setup'!$C$25>=C13,'Audit Setup'!$C$25<=C13+4),"⚑ DRAFT TO EXEC ",""),IF(AND('Audit Setup'!$C$26>=C13,'Audit Setup'!$C$26<=C13+4),"⚑ EXIT CONFERENCE ",""),IF(AND('Audit Setup'!$C$27>=C13,'Audit Setup'!$C$27<=C13+4),"⚑ MGMT RESPONSES DUE ",""),IF(AND('Audit Setup'!$C$32>=C13,'Audit Setup'!$C$32<=C13+4),"⚑ REPORT RELEASE ",""))))
A14: =IF(7<='Audit Setup'!$B$12,"PL-"&7,"") | C14: =C13+7 | D14: 0 | E14: =-COUNTIFS('Holidays & Skeleton'!$B$5:$B$25,">="&C14,'Holidays & Skeleton'!$B$5:$B$25,"<="&(C14+4))*'Audit Setup'!$B$7 | F14: =-COUNTIFS('Holidays & Skeleton'!$B$29:$B$36,">="&C14,'Holidays & Skeleton'!$B$29:$B$36,"<="&(C14+4))*'Audit Setup'!$B$7 | G14: 0 | H14: =CEILING(MAX(0,SUM(D14:G14)),1) | K14: 0 | L14: =IF(NOT(ISNUMBER(C14)),"",TRIM(CONCATENATE(IF(AND('Audit Setup'!$C$20>=C14,'Audit Setup'!$C$20<=C14+4),"⚑ KICKOFF ",""),IF(AND('Audit Setup'!$C$21>=C14,'Audit Setup'!$C$21<=C14+4),"⚑ END OF PLANNING ",""),IF(AND('Audit Setup'!$C$22>=C14,'Audit Setup'!$C$22<=C14+4),"⚑ OUTLINE TO EXEC ",""),IF(AND('Audit Setup'!$C$23>=C14,'Audit Setup'!$C$23<=C14+4),"⚑ ON-TARGET ",""),IF(AND('Audit Setup'!$C$25>=C14,'Audit Setup'!$C$25<=C14+4),"⚑ DRAFT TO EXEC ",""),IF(AND('Audit Setup'!$C$26>=C14,'Audit Setup'!$C$26<=C14+4),"⚑ EXIT CONFERENCE ",""),IF(AND('Audit Setup'!$C$27>=C14,'Audit Setup'!$C$27<=C14+4),"⚑ MGMT RESPONSES DUE ",""),IF(AND('Audit Setup'!$C$32>=C14,'Audit Setup'!$C$32<=C14+4),"⚑ REPORT RELEASE ",""))))
A15: =IF(8<='Audit Setup'!$B$12,"PL-"&8,"") | C15: =C14+7 | D15: 0 | E15: =-COUNTIFS('Holidays & Skeleton'!$B$5:$B$25,">="&C15,'Holidays & Skeleton'!$B$5:$B$25,"<="&(C15+4))*'Audit Setup'!$B$7 | F15: =-COUNTIFS('Holidays & Skeleton'!$B$29:$B$36,">="&C15,'Holidays & Skeleton'!$B$29:$B$36,"<="&(C15+4))*'Audit Setup'!$B$7 | G15: 0 | H15: =CEILING(MAX(0,SUM(D15:G15)),1) | K15: 0 | L15: =IF(NOT(ISNUMBER(C15)),"",TRIM(CONCATENATE(IF(AND('Audit Setup'!$C$20>=C15,'Audit Setup'!$C$20<=C15+4),"⚑ KICKOFF ",""),IF(AND('Audit Setup'!$C$21>=C15,'Audit Setup'!$C$21<=C15+4),"⚑ END OF PLANNING ",""),IF(AND('Audit Setup'!$C$22>=C15,'Audit Setup'!$C$22<=C15+4),"⚑ OUTLINE TO EXEC ",""),IF(AND('Audit Setup'!$C$23>=C15,'Audit Setup'!$C$23<=C15+4),"⚑ ON-TARGET ",""),IF(AND('Audit Setup'!$C$25>=C15,'Audit Setup'!$C$25<=C15+4),"⚑ DRAFT TO EXEC ",""),IF(AND('Audit Setup'!$C$26>=C15,'Audit Setup'!$C$26<=C15+4),"⚑ EXIT CONFERENCE ",""),IF(AND('Audit Setup'!$C$27>=C15,'Audit Setup'!$C$27<=C15+4),"⚑ MGMT RESPONSES DUE ",""),IF(AND('Audit Setup'!$C$32>=C15,'Audit Setup'!$C$32<=C15+4),"⚑ REPORT RELEASE ",""))))
A16: =IF(9<='Audit Setup'!$B$12,"PL-"&9,"") | C16: =C15+7 | D16: 0 | E16: =-COUNTIFS('Holidays & Skeleton'!$B$5:$B$25,">="&C16,'Holidays & Skeleton'!$B$5:$B$25,"<="&(C16+4))*'Audit Setup'!$B$7 | F16: =-COUNTIFS('Holidays & Skeleton'!$B$29:$B$36,">="&C16,'Holidays & Skeleton'!$B$29:$B$36,"<="&(C16+4))*'Audit Setup'!$B$7 | G16: 0 | H16: =CEILING(MAX(0,SUM(D16:G16)),1) | K16: 0 | L16: =IF(NOT(ISNUMBER(C16)),"",TRIM(CONCATENATE(IF(AND('Audit Setup'!$C$20>=C16,'Audit Setup'!$C$20<=C16+4),"⚑ KICKOFF ",""),IF(AND('Audit Setup'!$C$21>=C16,'Audit Setup'!$C$21<=C16+4),"⚑ END OF PLANNING ",""),IF(AND('Audit Setup'!$C$22>=C16,'Audit Setup'!$C$22<=C16+4),"⚑ OUTLINE TO EXEC ",""),IF(AND('Audit Setup'!$C$23>=C16,'Audit Setup'!$C$23<=C16+4),"⚑ ON-TARGET ",""),IF(AND('Audit Setup'!$C$25>=C16,'Audit Setup'!$C$25<=C16+4),"⚑ DRAFT TO EXEC ",""),IF(AND('Audit Setup'!$C$26>=C16,'Audit Setup'!$C$26<=C16+4),"⚑ EXIT CONFERENCE ",""),IF(AND('Audit Setup'!$C$27>=C16,'Audit Setup'!$C$27<=C16+4),"⚑ MGMT RESPONSES DUE ",""),IF(AND('Audit Setup'!$C$32>=C16,'Audit Setup'!$C$32<=C16+4),"⚑ REPORT RELEASE ",""))))
A17: =IF(10<='Audit Setup'!$B$12,"PL-"&10,"") | C17: =C16+7 | D17: 0 | E17: =-COUNTIFS('Holidays & Skeleton'!$B$5:$B$25,">="&C17,'Holidays & Skeleton'!$B$5:$B$25,"<="&(C17+4))*'Audit Setup'!$B$7 | F17: =-COUNTIFS('Holidays & Skeleton'!$B$29:$B$36,">="&C17,'Holidays & Skeleton'!$B$29:$B$36,"<="&(C17+4))*'Audit Setup'!$B$7 | G17: 0 | H17: =CEILING(MAX(0,SUM(D17:G17)),1) | K17: 0 | L17: =IF(NOT(ISNUMBER(C17)),"",TRIM(CONCATENATE(IF(AND('Audit Setup'!$C$20>=C17,'Audit Setup'!$C$20<=C17+4),"⚑ KICKOFF ",""),IF(AND('Audit Setup'!$C$21>=C17,'Audit Setup'!$C$21<=C17+4),"⚑ END OF PLANNING ",""),IF(AND('Audit Setup'!$C$22>=C17,'Audit Setup'!$C$22<=C17+4),"⚑ OUTLINE TO EXEC ",""),IF(AND('Audit Setup'!$C$23>=C17,'Audit Setup'!$C$23<=C17+4),"⚑ ON-TARGET ",""),IF(AND('Audit Setup'!$C$25>=C17,'Audit Setup'!$C$25<=C17+4),"⚑ DRAFT TO EXEC ",""),IF(AND('Audit Setup'!$C$26>=C17,'Audit Setup'!$C$26<=C17+4),"⚑ EXIT CONFERENCE ",""),IF(AND('Audit Setup'!$C$27>=C17,'Audit Setup'!$C$27<=C17+4),"⚑ MGMT RESPONSES DUE ",""),IF(AND('Audit Setup'!$C$32>=C17,'Audit Setup'!$C$32<=C17+4),"⚑ REPORT RELEASE ",""))))
A18: =IF(11<='Audit Setup'!$B$12,"PL-"&11,"") | C18: =C17+7 | D18: 0 | E18: =-COUNTIFS('Holidays & Skeleton'!$B$5:$B$25,">="&C18,'Holidays & Skeleton'!$B$5:$B$25,"<="&(C18+4))*'Audit Setup'!$B$7 | F18: =-COUNTIFS('Holidays & Skeleton'!$B$29:$B$36,">="&C18,'Holidays & Skeleton'!$B$29:$B$36,"<="&(C18+4))*'Audit Setup'!$B$7 | G18: 0 | H18: =CEILING(MAX(0,SUM(D18:G18)),1) | K18: 0 | L18: =IF(NOT(ISNUMBER(C18)),"",TRIM(CONCATENATE(IF(AND('Audit Setup'!$C$20>=C18,'Audit Setup'!$C$20<=C18+4),"⚑ KICKOFF ",""),IF(AND('Audit Setup'!$C$21>=C18,'Audit Setup'!$C$21<=C18+4),"⚑ END OF PLANNING ",""),IF(AND('Audit Setup'!$C$22>=C18,'Audit Setup'!$C$22<=C18+4),"⚑ OUTLINE TO EXEC ",""),IF(AND('Audit Setup'!$C$23>=C18,'Audit Setup'!$C$23<=C18+4),"⚑ ON-TARGET ",""),IF(AND('Audit Setup'!$C$25>=C18,'Audit Setup'!$C$25<=C18+4),"⚑ DRAFT TO EXEC ",""),IF(AND('Audit Setup'!$C$26>=C18,'Audit Setup'!$C$26<=C18+4),"⚑ EXIT CONFERENCE ",""),IF(AND('Audit Setup'!$C$27>=C18,'Audit Setup'!$C$27<=C18+4),"⚑ MGMT RESPONSES DUE ",""),IF(AND('Audit Setup'!$C$32>=C18,'Audit Setup'!$C$32<=C18+4),"⚑ REPORT RELEASE ",""))))
A19: =IF(12<='Audit Setup'!$B$12,"PL-"&12,"") | C19: =C18+7 | D19: 0 | E19: =-COUNTIFS('Holidays & Skeleton'!$B$5:$B$25,">="&C19,'Holidays & Skeleton'!$B$5:$B$25,"<="&(C19+4))*'Audit Setup'!$B$7 | F19: =-COUNTIFS('Holidays & Skeleton'!$B$29:$B$36,">="&C19,'Holidays & Skeleton'!$B$29:$B$36,"<="&(C19+4))*'Audit Setup'!$B$7 | G19: 0 | H19: =CEILING(MAX(0,SUM(D19:G19)),1) | K19: 0 | L19: =IF(NOT(ISNUMBER(C19)),"",TRIM(CONCATENATE(IF(AND('Audit Setup'!$C$20>=C19,'Audit Setup'!$C$20<=C19+4),"⚑ KICKOFF ",""),IF(AND('Audit Setup'!$C$21>=C19,'Audit Setup'!$C$21<=C19+4),"⚑ END OF PLANNING ",""),IF(AND('Audit Setup'!$C$22>=C19,'Audit Setup'!$C$22<=C19+4),"⚑ OUTLINE TO EXEC ",""),IF(AND('Audit Setup'!$C$23>=C19,'Audit Setup'!$C$23<=C19+4),"⚑ ON-TARGET ",""),IF(AND('Audit Setup'!$C$25>=C19,'Audit Setup'!$C$25<=C19+4),"⚑ DRAFT TO EXEC ",""),IF(AND('Audit Setup'!$C$26>=C19,'Audit Setup'!$C$26<=C19+4),"⚑ EXIT CONFERENCE ",""),IF(AND('Audit Setup'!$C$27>=C19,'Audit Setup'!$C$27<=C19+4),"⚑ MGMT RESPONSES DUE ",""),IF(AND('Audit Setup'!$C$32>=C19,'Audit Setup'!$C$32<=C19+4),"⚑ REPORT RELEASE ",""))))
A20: =IF(13<='Audit Setup'!$B$12,"PL-"&13,"") | C20: =C19+7 | D20: 0 | E20: =-COUNTIFS('Holidays & Skeleton'!$B$5:$B$25,">="&C20,'Holidays & Skeleton'!$B$5:$B$25,"<="&(C20+4))*'Audit Setup'!$B$7 | F20: =-COUNTIFS('Holidays & Skeleton'!$B$29:$B$36,">="&C20,'Holidays & Skeleton'!$B$29:$B$36,"<="&(C20+4))*'Audit Setup'!$B$7 | G20: 0 | H20: =CEILING(MAX(0,SUM(D20:G20)),1) | K20: 0 | L20: =IF(NOT(ISNUMBER(C20)),"",TRIM(CONCATENATE(IF(AND('Audit Setup'!$C$20>=C20,'Audit Setup'!$C$20<=C20+4),"⚑ KICKOFF ",""),IF(AND('Audit Setup'!$C$21>=C20,'Audit Setup'!$C$21<=C20+4),"⚑ END OF PLANNING ",""),IF(AND('Audit Setup'!$C$22>=C20,'Audit Setup'!$C$22<=C20+4),"⚑ OUTLINE TO EXEC ",""),IF(AND('Audit Setup'!$C$23>=C20,'Audit Setup'!$C$23<=C20+4),"⚑ ON-TARGET ",""),IF(AND('Audit Setup'!$C$25>=C20,'Audit Setup'!$C$25<=C20+4),"⚑ DRAFT TO EXEC ",""),IF(AND('Audit Setup'!$C$26>=C20,'Audit Setup'!$C$26<=C20+4),"⚑ EXIT CONFERENCE ",""),IF(AND('Audit Setup'!$C$27>=C20,'Audit Setup'!$C$27<=C20+4),"⚑ MGMT RESPONSES DUE ",""),IF(AND('Audit Setup'!$C$32>=C20,'Audit Setup'!$C$32<=C20+4),"⚑ REPORT RELEASE ",""))))
A21: =IF(14<='Audit Setup'!$B$12,"PL-"&14,"") | C21: =C20+7 | D21: 0 | E21: =-COUNTIFS('Holidays & Skeleton'!$B$5:$B$25,">="&C21,'Holidays & Skeleton'!$B$5:$B$25,"<="&(C21+4))*'Audit Setup'!$B$7 | F21: =-COUNTIFS('Holidays & Skeleton'!$B$29:$B$36,">="&C21,'Holidays & Skeleton'!$B$29:$B$36,"<="&(C21+4))*'Audit Setup'!$B$7 | G21: 0 | H21: =CEILING(MAX(0,SUM(D21:G21)),1) | K21: 0 | L21: =IF(NOT(ISNUMBER(C21)),"",TRIM(CONCATENATE(IF(AND('Audit Setup'!$C$20>=C21,'Audit Setup'!$C$20<=C21+4),"⚑ KICKOFF ",""),IF(AND('Audit Setup'!$C$21>=C21,'Audit Setup'!$C$21<=C21+4),"⚑ END OF PLANNING ",""),IF(AND('Audit Setup'!$C$22>=C21,'Audit Setup'!$C$22<=C21+4),"⚑ OUTLINE TO EXEC ",""),IF(AND('Audit Setup'!$C$23>=C21,'Audit Setup'!$C$23<=C21+4),"⚑ ON-TARGET ",""),IF(AND('Audit Setup'!$C$25>=C21,'Audit Setup'!$C$25<=C21+4),"⚑ DRAFT TO EXEC ",""),IF(AND('Audit Setup'!$C$26>=C21,'Audit Setup'!$C$26<=C21+4),"⚑ EXIT CONFERENCE ",""),IF(AND('Audit Setup'!$C$27>=C21,'Audit Setup'!$C$27<=C21+4),"⚑ MGMT RESPONSES DUE ",""),IF(AND('Audit Setup'!$C$32>=C21,'Audit Setup'!$C$32<=C21+4),"⚑ REPORT RELEASE ",""))))
A22: =IF(15<='Audit Setup'!$B$12,"PL-"&15,"") | C22: =C21+7 | D22: 0 | E22: =-COUNTIFS('Holidays & Skeleton'!$B$5:$B$25,">="&C22,'Holidays & Skeleton'!$B$5:$B$25,"<="&(C22+4))*'Audit Setup'!$B$7 | F22: =-COUNTIFS('Holidays & Skeleton'!$B$29:$B$36,">="&C22,'Holidays & Skeleton'!$B$29:$B$36,"<="&(C22+4))*'Audit Setup'!$B$7 | G22: 0 | H22: =CEILING(MAX(0,SUM(D22:G22)),1) | K22: 0 | L22: =IF(NOT(ISNUMBER(C22)),"",TRIM(CONCATENATE(IF(AND('Audit Setup'!$C$20>=C22,'Audit Setup'!$C$20<=C22+4),"⚑ KICKOFF ",""),IF(AND('Audit Setup'!$C$21>=C22,'Audit Setup'!$C$21<=C22+4),"⚑ END OF PLANNING ",""),IF(AND('Audit Setup'!$C$22>=C22,'Audit Setup'!$C$22<=C22+4),"⚑ OUTLINE TO EXEC ",""),IF(AND('Audit Setup'!$C$23>=C22,'Audit Setup'!$C$23<=C22+4),"⚑ ON-TARGET ",""),IF(AND('Audit Setup'!$C$25>=C22,'Audit Setup'!$C$25<=C22+4),"⚑ DRAFT TO EXEC ",""),IF(AND('Audit Setup'!$C$26>=C22,'Audit Setup'!$C$26<=C22+4),"⚑ EXIT CONFERENCE ",""),IF(AND('Audit Setup'!$C$27>=C22,'Audit Setup'!$C$27<=C22+4),"⚑ MGMT RESPONSES DUE ",""),IF(AND('Audit Setup'!$C$32>=C22,'Audit Setup'!$C$32<=C22+4),"⚑ REPORT RELEASE ",""))))
A23: =IF(16<='Audit Setup'!$B$12,"PL-"&16,"") | C23: =C22+7 | D23: 0 | E23: =-COUNTIFS('Holidays & Skeleton'!$B$5:$B$25,">="&C23,'Holidays & Skeleton'!$B$5:$B$25,"<="&(C23+4))*'Audit Setup'!$B$7 | F23: =-COUNTIFS('Holidays & Skeleton'!$B$29:$B$36,">="&C23,'Holidays & Skeleton'!$B$29:$B$36,"<="&(C23+4))*'Audit Setup'!$B$7 | G23: 0 | H23: =CEILING(MAX(0,SUM(D23:G23)),1) | K23: 0 | L23: =IF(NOT(ISNUMBER(C23)),"",TRIM(CONCATENATE(IF(AND('Audit Setup'!$C$20>=C23,'Audit Setup'!$C$20<=C23+4),"⚑ KICKOFF ",""),IF(AND('Audit Setup'!$C$21>=C23,'Audit Setup'!$C$21<=C23+4),"⚑ END OF PLANNING ",""),IF(AND('Audit Setup'!$C$22>=C23,'Audit Setup'!$C$22<=C23+4),"⚑ OUTLINE TO EXEC ",""),IF(AND('Audit Setup'!$C$23>=C23,'Audit Setup'!$C$23<=C23+4),"⚑ ON-TARGET ",""),IF(AND('Audit Setup'!$C$25>=C23,'Audit Setup'!$C$25<=C23+4),"⚑ DRAFT TO EXEC ",""),IF(AND('Audit Setup'!$C$26>=C23,'Audit Setup'!$C$26<=C23+4),"⚑ EXIT CONFERENCE ",""),IF(AND('Audit Setup'!$C$27>=C23,'Audit Setup'!$C$27<=C23+4),"⚑ MGMT RESPONSES DUE ",""),IF(AND('Audit Setup'!$C$32>=C23,'Audit Setup'!$C$32<=C23+4),"⚑ REPORT RELEASE ",""))))
